{
  "cells": [
    {
      "cell_type": "markdown",
      "metadata": {
        "id": "view-in-github",
        "colab_type": "text"
      },
      "source": [
        "<a href=\"https://colab.research.google.com/github/Yosoy1408/skills-introduction-to-github/blob/main/Untitled1.ipynb\" target=\"_parent\"><img src=\"https://colab.research.google.com/assets/colab-badge.svg\" alt=\"Open In Colab\"/></a>"
      ]
    },
    {
      "cell_type": "code",
      "execution_count": null,
      "metadata": {
        "id": "3wbKn6W9VZKm"
      },
      "outputs": [],
      "source": [
        "!pip install python-telegram-bot==13.7"
      ]
    },
    {
      "cell_type": "code",
      "execution_count": null,
      "metadata": {
        "id": "-zuvIYeHVn6L"
      },
      "outputs": [],
      "source": [
        "import os\n",
        "import random\n",
        "import json\n",
        "import logging\n",
        "from datetime import datetime, timedelta\n",
        "from typing import Dict, List, Union\n",
        "from telegram import Update, InlineKeyboardButton, InlineKeyboardMarkup, ParseMode\n",
        "from telegram.ext import Updater, CommandHandler, CallbackQueryHandler, CallbackContext\n",
        "\n",
        "# Configuraci√≥n del token y logging\n",
        "TOKEN = \"7643294498:AAEJM1ftebsJmN1Jt2-lXkKA3l7bMcd7n0Q\"\n",
        "\n",
        "logging.basicConfig(\n",
        "    format='%(asctime)s - %(name)s - %(levelname)s - %(message)s',\n",
        "    level=logging.INFO\n",
        ")\n",
        "logger = logging.getLogger(__name__)"
      ]
    },
    {
      "cell_type": "code",
      "execution_count": null,
      "metadata": {
        "colab": {
          "base_uri": "https://localhost:8080/"
        },
        "id": "ygSMRBiJVvyT",
        "outputId": "20b5ac18-e13f-4082-f72a-c495862a26ae"
      },
      "outputs": [
        {
          "name": "stdout",
          "output_type": "stream",
          "text": [
            "‚úÖ Juego inicializado correctamente\n"
          ]
        }
      ],
      "source": [
        "# Constantes del juego\n",
        "LOGROS = {\n",
        "    'primer_construccion': {\n",
        "        'nombre': 'üè† Primera Construcci√≥n',\n",
        "        'descripcion': '¬°Completaste tu primera construcci√≥n!',\n",
        "        'recompensa': 100\n",
        "    },\n",
        "    'constructor_experto': {\n",
        "        'nombre': 'üë∑ Constructor Experto',\n",
        "        'descripcion': 'Alcanzaste el nivel 5 de construcci√≥n',\n",
        "        'recompensa': 500\n",
        "    }\n",
        "}\n",
        "\n",
        "NIVELES_CONSTRUCCION = {\n",
        "    1: {\n",
        "        'nombre': 'Casa B√°sica',\n",
        "        'requisitos': 0,\n",
        "        'recompensa': 100,\n",
        "        'descripcion': 'üè† Una casa simple pero acogedora'\n",
        "    },\n",
        "    2: {\n",
        "        'nombre': 'Casa Mejorada',\n",
        "        'requisitos': 1000,\n",
        "        'recompensa': 200,\n",
        "        'descripcion': 'üè° Una casa con mejores acabados'\n",
        "    },\n",
        "    3: {\n",
        "        'nombre': 'Casa Familiar',\n",
        "        'requisitos': 2500,\n",
        "        'recompensa': 500,\n",
        "        'descripcion': 'üèòÔ∏è Una casa perfecta para familias'\n",
        "    }\n",
        "}\n",
        "\n",
        "class DreamBuilderGame:\n",
        "    def __init__(self):\n",
        "        self.usuarios = {}\n",
        "        self.logros = LOGROS\n",
        "        self.niveles = NIVELES_CONSTRUCCION\n",
        "\n",
        "    def crear_usuario(self, user_id: int, nombre: str) -> str:\n",
        "        if user_id not in self.usuarios:\n",
        "            self.usuarios[user_id] = {\n",
        "                'nombre': nombre,\n",
        "                'nivel': 1,\n",
        "                'progreso': 0,\n",
        "                'monedas': 0,\n",
        "                'logros': [],\n",
        "                'ultima_construccion': None\n",
        "            }\n",
        "            return f\"¬°Bienvenido al juego, {nombre}! üéÆ\\nEst√°s participando en la campa√±a 'Casas para Todos'\"\n",
        "        return f\"¬°Bienvenido de nuevo, {nombre}! üéÆ\"\n",
        "\n",
        "    def construir(self, user_id: int) -> str:\n",
        "        if user_id not in self.usuarios:\n",
        "            return \"‚ùå Necesitas registrarte primero con /start\"\n",
        "\n",
        "        usuario = self.usuarios[user_id]\n",
        "        ahora = datetime.now()\n",
        "\n",
        "        if usuario['ultima_construccion']:\n",
        "            ultima = usuario['ultima_construccion']\n",
        "            if isinstance(ultima, datetime) and (ahora - ultima) < timedelta(hours=24):\n",
        "                tiempo_restante = 24 - (ahora - ultima).total_seconds() / 3600\n",
        "                return f\"‚è≥ Debes esperar {tiempo_restante:.1f} horas para construir de nuevo.\"\n",
        "\n",
        "        progreso = random.randint(5, 15)\n",
        "        usuario['progreso'] += progreso\n",
        "        usuario['ultima_construccion'] = ahora\n",
        "\n",
        "        if usuario['progreso'] >= 100:\n",
        "            if usuario['nivel'] < len(self.niveles):\n",
        "                usuario['nivel'] += 1\n",
        "                usuario['progreso'] = 0\n",
        "                usuario['monedas'] += self.niveles[usuario['nivel']]['recompensa']\n",
        "                return f\"üéâ ¬°Felicidades! Has completado el nivel {usuario['nivel']-1}.\\n\" \\\n",
        "                       f\"Recompensa: {self.niveles[usuario['nivel']]['recompensa']} monedas üí∞\"\n",
        "            else:\n",
        "                return \"üèÜ ¬°Has alcanzado el nivel m√°ximo!\"\n",
        "\n",
        "        return f\"üèóÔ∏è Progreso: {usuario['progreso']}%. ¬°Sigue construyendo!\"\n",
        "\n",
        "    def ver_perfil(self, user_id: int) -> str:\n",
        "        if user_id not in self.usuarios:\n",
        "            return \"‚ùå Necesitas registrarte primero con /start\"\n",
        "\n",
        "        usuario = self.usuarios[user_id]\n",
        "        nivel_actual = self.niveles[usuario['nivel']]\n",
        "\n",
        "        return (\n",
        "            f\"üë§ *Perfil de {usuario['nombre']}*\\n\\n\"\n",
        "            f\"üèóÔ∏è Nivel: {usuario['nivel']} ({nivel_actual['nombre']})\\n\"\n",
        "            f\"üìä Progreso: {usuario['progreso']}%\\n\"\n",
        "            f\"üí∞ Monedas: {usuario['monedas']}\\n\"\n",
        "            f\"üèÜ Logros: {len(usuario['logros'])}\\n\\n\"\n",
        "            f\"*Nivel actual:* {nivel_actual['descripcion']}\"\n",
        "        )\n",
        "\n",
        "# Inicializar el juego\n",
        "game = DreamBuilderGame()\n",
        "print(\"‚úÖ Juego inicializado correctamente\")"
      ]
    },
    {
      "cell_type": "code",
      "execution_count": null,
      "metadata": {
        "id": "fOs4j64nV-9f"
      },
      "outputs": [],
      "source": [
        "def start(update: Update, context: CallbackContext) -> None:\n",
        "    user = update.effective_user\n",
        "    mensaje = game.crear_usuario(user.id, user.first_name)\n",
        "\n",
        "    keyboard = [\n",
        "        [InlineKeyboardButton(\"üèóÔ∏è Construir\", callback_data='construir')],\n",
        "        [InlineKeyboardButton(\"üë§ Mi Perfil\", callback_data='perfil')],\n",
        "        [InlineKeyboardButton(\"üèÜ Logros\", callback_data='logros')]\n",
        "    ]\n",
        "    reply_markup = InlineKeyboardMarkup(keyboard)\n",
        "\n",
        "    update.message.reply_text(\n",
        "        f\"{mensaje}\\n\\n\"\n",
        "        \"¬øQu√© te gustar√≠a hacer?\",\n",
        "        reply_markup=reply_markup\n",
        "    )\n",
        "\n",
        "def button(update: Update, context: CallbackContext) -> None:\n",
        "    query = update.callback_query\n",
        "    query.answer()\n",
        "\n",
        "    if query.data == 'construir':\n",
        "        respuesta = game.construir(query.from_user.id)\n",
        "        query.edit_message_text(text=respuesta)\n",
        "    elif query.data == 'perfil':\n",
        "        respuesta = game.ver_perfil(query.from_user.id)\n",
        "        query.edit_message_text(text=respuesta, parse_mode=ParseMode.MARKDOWN)\n",
        "    elif query.data == 'logros':\n",
        "        usuario = game.usuarios.get(query.from_user.id)\n",
        "        if usuario:\n",
        "            respuesta = \"üèÜ *Tus logros:*\\n\\n\"\n",
        "            if usuario['logros']:\n",
        "                for logro in usuario['logros']:\n",
        "                    logro_info = game.logros[logro]\n",
        "                    respuesta += f\"‚Ä¢ {logro_info['nombre']}: {logro_info['descripcion']}\\n\"\n",
        "            else:\n",
        "                respuesta += \"A√∫n no has conseguido ning√∫n logro. ¬°Sigue jugando!\"\n",
        "        else:\n",
        "            respuesta = \"‚ùå Necesitas registrarte primero con /start\"\n",
        "        query.edit_message_text(text=respuesta, parse_mode=ParseMode.MARKDOWN)"
      ]
    },
    {
      "cell_type": "code",
      "execution_count": null,
      "metadata": {
        "colab": {
          "background_save": true,
          "base_uri": "https://localhost:8080/"
        },
        "id": "53MfsurEWLdL",
        "outputId": "f31d4cb6-2b59-44a8-97f7-50c36ba146b2"
      },
      "outputs": [
        {
          "name": "stdout",
          "output_type": "stream",
          "text": [
            "¬°Bot iniciado correctamente! üöÄ\n",
            "Usa Ctrl+C para detener el bot\n"
          ]
        },
        {
          "name": "stderr",
          "output_type": "stream",
          "text": [
            "ERROR:telegram.ext.updater:Error while getting Updates: Conflict: terminated by other getUpdates request; make sure that only one bot instance is running\n",
            "ERROR:telegram.ext.dispatcher:No error handlers are registered, logging exception.\n",
            "Traceback (most recent call last):\n",
            "  File \"/usr/local/lib/python3.10/dist-packages/telegram/ext/updater.py\", line 646, in _network_loop_retry\n",
            "    if not action_cb():\n",
            "  File \"/usr/local/lib/python3.10/dist-packages/telegram/ext/updater.py\", line 597, in polling_action_cb\n",
            "    updates = self.bot.get_updates(\n",
            "  File \"/usr/local/lib/python3.10/dist-packages/telegram/ext/extbot.py\", line 222, in get_updates\n",
            "    updates = super().get_updates(\n",
            "  File \"/usr/local/lib/python3.10/dist-packages/telegram/bot.py\", line 130, in decorator\n",
            "    result = func(*args, **kwargs)\n",
            "  File \"/usr/local/lib/python3.10/dist-packages/telegram/bot.py\", line 2861, in get_updates\n",
            "    self._post(\n",
            "  File \"/usr/local/lib/python3.10/dist-packages/telegram/bot.py\", line 295, in _post\n",
            "    return self.request.post(\n",
            "  File \"/usr/local/lib/python3.10/dist-packages/telegram/utils/request.py\", line 356, in post\n",
            "    result = self._request_wrapper(\n",
            "  File \"/usr/local/lib/python3.10/dist-packages/telegram/utils/request.py\", line 283, in _request_wrapper\n",
            "    raise Conflict(message)\n",
            "telegram.error.Conflict: Conflict: terminated by other getUpdates request; make sure that only one bot instance is running\n",
            "ERROR:telegram.ext.updater:Error while getting Updates: Conflict: terminated by other getUpdates request; make sure that only one bot instance is running\n",
            "ERROR:telegram.ext.dispatcher:No error handlers are registered, logging exception.\n",
            "Traceback (most recent call last):\n",
            "  File \"/usr/local/lib/python3.10/dist-packages/telegram/ext/updater.py\", line 646, in _network_loop_retry\n",
            "    if not action_cb():\n",
            "  File \"/usr/local/lib/python3.10/dist-packages/telegram/ext/updater.py\", line 597, in polling_action_cb\n",
            "    updates = self.bot.get_updates(\n",
            "  File \"/usr/local/lib/python3.10/dist-packages/telegram/ext/extbot.py\", line 222, in get_updates\n",
            "    updates = super().get_updates(\n",
            "  File \"/usr/local/lib/python3.10/dist-packages/telegram/bot.py\", line 130, in decorator\n",
            "    result = func(*args, **kwargs)\n",
            "  File \"/usr/local/lib/python3.10/dist-packages/telegram/bot.py\", line 2861, in get_updates\n",
            "    self._post(\n",
            "  File \"/usr/local/lib/python3.10/dist-packages/telegram/bot.py\", line 295, in _post\n",
            "    return self.request.post(\n",
            "  File \"/usr/local/lib/python3.10/dist-packages/telegram/utils/request.py\", line 356, in post\n",
            "    result = self._request_wrapper(\n",
            "  File \"/usr/local/lib/python3.10/dist-packages/telegram/utils/request.py\", line 283, in _request_wrapper\n",
            "    raise Conflict(message)\n",
            "telegram.error.Conflict: Conflict: terminated by other getUpdates request; make sure that only one bot instance is running\n",
            "ERROR:telegram.ext.updater:Error while getting Updates: Conflict: terminated by other getUpdates request; make sure that only one bot instance is running\n",
            "ERROR:telegram.ext.dispatcher:No error handlers are registered, logging exception.\n",
            "Traceback (most recent call last):\n",
            "  File \"/usr/local/lib/python3.10/dist-packages/telegram/ext/updater.py\", line 646, in _network_loop_retry\n",
            "    if not action_cb():\n",
            "  File \"/usr/local/lib/python3.10/dist-packages/telegram/ext/updater.py\", line 597, in polling_action_cb\n",
            "    updates = self.bot.get_updates(\n",
            "  File \"/usr/local/lib/python3.10/dist-packages/telegram/ext/extbot.py\", line 222, in get_updates\n",
            "    updates = super().get_updates(\n",
            "  File \"/usr/local/lib/python3.10/dist-packages/telegram/bot.py\", line 130, in decorator\n",
            "    result = func(*args, **kwargs)\n",
            "  File \"/usr/local/lib/python3.10/dist-packages/telegram/bot.py\", line 2861, in get_updates\n",
            "    self._post(\n",
            "  File \"/usr/local/lib/python3.10/dist-packages/telegram/bot.py\", line 295, in _post\n",
            "    return self.request.post(\n",
            "  File \"/usr/local/lib/python3.10/dist-packages/telegram/utils/request.py\", line 356, in post\n",
            "    result = self._request_wrapper(\n",
            "  File \"/usr/local/lib/python3.10/dist-packages/telegram/utils/request.py\", line 283, in _request_wrapper\n",
            "    raise Conflict(message)\n",
            "telegram.error.Conflict: Conflict: terminated by other getUpdates request; make sure that only one bot instance is running\n",
            "ERROR:telegram.ext.updater:Error while getting Updates: Conflict: terminated by other getUpdates request; make sure that only one bot instance is running\n",
            "ERROR:telegram.ext.dispatcher:No error handlers are registered, logging exception.\n",
            "Traceback (most recent call last):\n",
            "  File \"/usr/local/lib/python3.10/dist-packages/telegram/ext/updater.py\", line 646, in _network_loop_retry\n",
            "    if not action_cb():\n",
            "  File \"/usr/local/lib/python3.10/dist-packages/telegram/ext/updater.py\", line 597, in polling_action_cb\n",
            "    updates = self.bot.get_updates(\n",
            "  File \"/usr/local/lib/python3.10/dist-packages/telegram/ext/extbot.py\", line 222, in get_updates\n",
            "    updates = super().get_updates(\n",
            "  File \"/usr/local/lib/python3.10/dist-packages/telegram/bot.py\", line 130, in decorator\n",
            "    result = func(*args, **kwargs)\n",
            "  File \"/usr/local/lib/python3.10/dist-packages/telegram/bot.py\", line 2861, in get_updates\n",
            "    self._post(\n",
            "  File \"/usr/local/lib/python3.10/dist-packages/telegram/bot.py\", line 295, in _post\n",
            "    return self.request.post(\n",
            "  File \"/usr/local/lib/python3.10/dist-packages/telegram/utils/request.py\", line 356, in post\n",
            "    result = self._request_wrapper(\n",
            "  File \"/usr/local/lib/python3.10/dist-packages/telegram/utils/request.py\", line 283, in _request_wrapper\n",
            "    raise Conflict(message)\n",
            "telegram.error.Conflict: Conflict: terminated by other getUpdates request; make sure that only one bot instance is running\n",
            "ERROR:telegram.ext.updater:Error while getting Updates: Conflict: terminated by other getUpdates request; make sure that only one bot instance is running\n",
            "ERROR:telegram.ext.dispatcher:No error handlers are registered, logging exception.\n",
            "Traceback (most recent call last):\n",
            "  File \"/usr/local/lib/python3.10/dist-packages/telegram/ext/updater.py\", line 646, in _network_loop_retry\n",
            "    if not action_cb():\n",
            "  File \"/usr/local/lib/python3.10/dist-packages/telegram/ext/updater.py\", line 597, in polling_action_cb\n",
            "    updates = self.bot.get_updates(\n",
            "  File \"/usr/local/lib/python3.10/dist-packages/telegram/ext/extbot.py\", line 222, in get_updates\n",
            "    updates = super().get_updates(\n",
            "  File \"/usr/local/lib/python3.10/dist-packages/telegram/bot.py\", line 130, in decorator\n",
            "    result = func(*args, **kwargs)\n",
            "  File \"/usr/local/lib/python3.10/dist-packages/telegram/bot.py\", line 2861, in get_updates\n",
            "    self._post(\n",
            "  File \"/usr/local/lib/python3.10/dist-packages/telegram/bot.py\", line 295, in _post\n",
            "    return self.request.post(\n",
            "  File \"/usr/local/lib/python3.10/dist-packages/telegram/utils/request.py\", line 356, in post\n",
            "    result = self._request_wrapper(\n",
            "  File \"/usr/local/lib/python3.10/dist-packages/telegram/utils/request.py\", line 283, in _request_wrapper\n",
            "    raise Conflict(message)\n",
            "telegram.error.Conflict: Conflict: terminated by other getUpdates request; make sure that only one bot instance is running\n",
            "ERROR:telegram.ext.updater:Error while getting Updates: Conflict: terminated by other getUpdates request; make sure that only one bot instance is running\n",
            "ERROR:telegram.ext.dispatcher:No error handlers are registered, logging exception.\n",
            "Traceback (most recent call last):\n",
            "  File \"/usr/local/lib/python3.10/dist-packages/telegram/ext/updater.py\", line 646, in _network_loop_retry\n",
            "    if not action_cb():\n",
            "  File \"/usr/local/lib/python3.10/dist-packages/telegram/ext/updater.py\", line 597, in polling_action_cb\n",
            "    updates = self.bot.get_updates(\n",
            "  File \"/usr/local/lib/python3.10/dist-packages/telegram/ext/extbot.py\", line 222, in get_updates\n",
            "    updates = super().get_updates(\n",
            "  File \"/usr/local/lib/python3.10/dist-packages/telegram/bot.py\", line 130, in decorator\n",
            "    result = func(*args, **kwargs)\n",
            "  File \"/usr/local/lib/python3.10/dist-packages/telegram/bot.py\", line 2861, in get_updates\n",
            "    self._post(\n",
            "  File \"/usr/local/lib/python3.10/dist-packages/telegram/bot.py\", line 295, in _post\n",
            "    return self.request.post(\n",
            "  File \"/usr/local/lib/python3.10/dist-packages/telegram/utils/request.py\", line 356, in post\n",
            "    result = self._request_wrapper(\n",
            "  File \"/usr/local/lib/python3.10/dist-packages/telegram/utils/request.py\", line 283, in _request_wrapper\n",
            "    raise Conflict(message)\n",
            "telegram.error.Conflict: Conflict: terminated by other getUpdates request; make sure that only one bot instance is running\n",
            "ERROR:telegram.ext.updater:Error while getting Updates: Conflict: terminated by other getUpdates request; make sure that only one bot instance is running\n",
            "ERROR:telegram.ext.dispatcher:No error handlers are registered, logging exception.\n",
            "Traceback (most recent call last):\n",
            "  File \"/usr/local/lib/python3.10/dist-packages/telegram/ext/updater.py\", line 646, in _network_loop_retry\n",
            "    if not action_cb():\n",
            "  File \"/usr/local/lib/python3.10/dist-packages/telegram/ext/updater.py\", line 597, in polling_action_cb\n",
            "    updates = self.bot.get_updates(\n",
            "  File \"/usr/local/lib/python3.10/dist-packages/telegram/ext/extbot.py\", line 222, in get_updates\n",
            "    updates = super().get_updates(\n",
            "  File \"/usr/local/lib/python3.10/dist-packages/telegram/bot.py\", line 130, in decorator\n",
            "    result = func(*args, **kwargs)\n",
            "  File \"/usr/local/lib/python3.10/dist-packages/telegram/bot.py\", line 2861, in get_updates\n",
            "    self._post(\n",
            "  File \"/usr/local/lib/python3.10/dist-packages/telegram/bot.py\", line 295, in _post\n",
            "    return self.request.post(\n",
            "  File \"/usr/local/lib/python3.10/dist-packages/telegram/utils/request.py\", line 356, in post\n",
            "    result = self._request_wrapper(\n",
            "  File \"/usr/local/lib/python3.10/dist-packages/telegram/utils/request.py\", line 283, in _request_wrapper\n",
            "    raise Conflict(message)\n",
            "telegram.error.Conflict: Conflict: terminated by other getUpdates request; make sure that only one bot instance is running\n",
            "ERROR:telegram.ext.updater:Error while getting Updates: Conflict: terminated by other getUpdates request; make sure that only one bot instance is running\n",
            "ERROR:telegram.ext.dispatcher:No error handlers are registered, logging exception.\n",
            "Traceback (most recent call last):\n",
            "  File \"/usr/local/lib/python3.10/dist-packages/telegram/ext/updater.py\", line 646, in _network_loop_retry\n",
            "    if not action_cb():\n",
            "  File \"/usr/local/lib/python3.10/dist-packages/telegram/ext/updater.py\", line 597, in polling_action_cb\n",
            "    updates = self.bot.get_updates(\n",
            "  File \"/usr/local/lib/python3.10/dist-packages/telegram/ext/extbot.py\", line 222, in get_updates\n",
            "    updates = super().get_updates(\n",
            "  File \"/usr/local/lib/python3.10/dist-packages/telegram/bot.py\", line 130, in decorator\n",
            "    result = func(*args, **kwargs)\n",
            "  File \"/usr/local/lib/python3.10/dist-packages/telegram/bot.py\", line 2861, in get_updates\n",
            "    self._post(\n",
            "  File \"/usr/local/lib/python3.10/dist-packages/telegram/bot.py\", line 295, in _post\n",
            "    return self.request.post(\n",
            "  File \"/usr/local/lib/python3.10/dist-packages/telegram/utils/request.py\", line 356, in post\n",
            "    result = self._request_wrapper(\n",
            "  File \"/usr/local/lib/python3.10/dist-packages/telegram/utils/request.py\", line 283, in _request_wrapper\n",
            "    raise Conflict(message)\n",
            "telegram.error.Conflict: Conflict: terminated by other getUpdates request; make sure that only one bot instance is running\n",
            "ERROR:telegram.ext.updater:Error while getting Updates: Conflict: terminated by other getUpdates request; make sure that only one bot instance is running\n",
            "ERROR:telegram.ext.dispatcher:No error handlers are registered, logging exception.\n",
            "Traceback (most recent call last):\n",
            "  File \"/usr/local/lib/python3.10/dist-packages/telegram/ext/updater.py\", line 646, in _network_loop_retry\n",
            "    if not action_cb():\n",
            "  File \"/usr/local/lib/python3.10/dist-packages/telegram/ext/updater.py\", line 597, in polling_action_cb\n",
            "    updates = self.bot.get_updates(\n",
            "  File \"/usr/local/lib/python3.10/dist-packages/telegram/ext/extbot.py\", line 222, in get_updates\n",
            "    updates = super().get_updates(\n",
            "  File \"/usr/local/lib/python3.10/dist-packages/telegram/bot.py\", line 130, in decorator\n",
            "    result = func(*args, **kwargs)\n",
            "  File \"/usr/local/lib/python3.10/dist-packages/telegram/bot.py\", line 2861, in get_updates\n",
            "    self._post(\n",
            "  File \"/usr/local/lib/python3.10/dist-packages/telegram/bot.py\", line 295, in _post\n",
            "    return self.request.post(\n",
            "  File \"/usr/local/lib/python3.10/dist-packages/telegram/utils/request.py\", line 356, in post\n",
            "    result = self._request_wrapper(\n",
            "  File \"/usr/local/lib/python3.10/dist-packages/telegram/utils/request.py\", line 283, in _request_wrapper\n",
            "    raise Conflict(message)\n",
            "telegram.error.Conflict: Conflict: terminated by other getUpdates request; make sure that only one bot instance is running\n",
            "ERROR:telegram.ext.updater:Error while getting Updates: Conflict: terminated by other getUpdates request; make sure that only one bot instance is running\n",
            "ERROR:telegram.ext.dispatcher:No error handlers are registered, logging exception.\n",
            "Traceback (most recent call last):\n",
            "  File \"/usr/local/lib/python3.10/dist-packages/telegram/ext/updater.py\", line 646, in _network_loop_retry\n",
            "    if not action_cb():\n",
            "  File \"/usr/local/lib/python3.10/dist-packages/telegram/ext/updater.py\", line 597, in polling_action_cb\n",
            "    updates = self.bot.get_updates(\n",
            "  File \"/usr/local/lib/python3.10/dist-packages/telegram/ext/extbot.py\", line 222, in get_updates\n",
            "    updates = super().get_updates(\n",
            "  File \"/usr/local/lib/python3.10/dist-packages/telegram/bot.py\", line 130, in decorator\n",
            "    result = func(*args, **kwargs)\n",
            "  File \"/usr/local/lib/python3.10/dist-packages/telegram/bot.py\", line 2861, in get_updates\n",
            "    self._post(\n",
            "  File \"/usr/local/lib/python3.10/dist-packages/telegram/bot.py\", line 295, in _post\n",
            "    return self.request.post(\n",
            "  File \"/usr/local/lib/python3.10/dist-packages/telegram/utils/request.py\", line 356, in post\n",
            "    result = self._request_wrapper(\n",
            "  File \"/usr/local/lib/python3.10/dist-packages/telegram/utils/request.py\", line 283, in _request_wrapper\n",
            "    raise Conflict(message)\n",
            "telegram.error.Conflict: Conflict: terminated by other getUpdates request; make sure that only one bot instance is running\n",
            "ERROR:telegram.ext.updater:Error while getting Updates: Conflict: terminated by other getUpdates request; make sure that only one bot instance is running\n",
            "ERROR:telegram.ext.dispatcher:No error handlers are registered, logging exception.\n",
            "Traceback (most recent call last):\n",
            "  File \"/usr/local/lib/python3.10/dist-packages/telegram/ext/updater.py\", line 646, in _network_loop_retry\n",
            "    if not action_cb():\n",
            "  File \"/usr/local/lib/python3.10/dist-packages/telegram/ext/updater.py\", line 597, in polling_action_cb\n",
            "    updates = self.bot.get_updates(\n",
            "  File \"/usr/local/lib/python3.10/dist-packages/telegram/ext/extbot.py\", line 222, in get_updates\n",
            "    updates = super().get_updates(\n",
            "  File \"/usr/local/lib/python3.10/dist-packages/telegram/bot.py\", line 130, in decorator\n",
            "    result = func(*args, **kwargs)\n",
            "  File \"/usr/local/lib/python3.10/dist-packages/telegram/bot.py\", line 2861, in get_updates\n",
            "    self._post(\n",
            "  File \"/usr/local/lib/python3.10/dist-packages/telegram/bot.py\", line 295, in _post\n",
            "    return self.request.post(\n",
            "  File \"/usr/local/lib/python3.10/dist-packages/telegram/utils/request.py\", line 356, in post\n",
            "    result = self._request_wrapper(\n",
            "  File \"/usr/local/lib/python3.10/dist-packages/telegram/utils/request.py\", line 283, in _request_wrapper\n",
            "    raise Conflict(message)\n",
            "telegram.error.Conflict: Conflict: terminated by other getUpdates request; make sure that only one bot instance is running\n",
            "ERROR:telegram.ext.updater:Error while getting Updates: Conflict: terminated by other getUpdates request; make sure that only one bot instance is running\n",
            "ERROR:telegram.ext.dispatcher:No error handlers are registered, logging exception.\n",
            "Traceback (most recent call last):\n",
            "  File \"/usr/local/lib/python3.10/dist-packages/telegram/ext/updater.py\", line 646, in _network_loop_retry\n",
            "    if not action_cb():\n",
            "  File \"/usr/local/lib/python3.10/dist-packages/telegram/ext/updater.py\", line 597, in polling_action_cb\n",
            "    updates = self.bot.get_updates(\n",
            "  File \"/usr/local/lib/python3.10/dist-packages/telegram/ext/extbot.py\", line 222, in get_updates\n",
            "    updates = super().get_updates(\n",
            "  File \"/usr/local/lib/python3.10/dist-packages/telegram/bot.py\", line 130, in decorator\n",
            "    result = func(*args, **kwargs)\n",
            "  File \"/usr/local/lib/python3.10/dist-packages/telegram/bot.py\", line 2861, in get_updates\n",
            "    self._post(\n",
            "  File \"/usr/local/lib/python3.10/dist-packages/telegram/bot.py\", line 295, in _post\n",
            "    return self.request.post(\n",
            "  File \"/usr/local/lib/python3.10/dist-packages/telegram/utils/request.py\", line 356, in post\n",
            "    result = self._request_wrapper(\n",
            "  File \"/usr/local/lib/python3.10/dist-packages/telegram/utils/request.py\", line 283, in _request_wrapper\n",
            "    raise Conflict(message)\n",
            "telegram.error.Conflict: Conflict: terminated by other getUpdates request; make sure that only one bot instance is running\n",
            "ERROR:telegram.ext.updater:Error while getting Updates: Conflict: terminated by other getUpdates request; make sure that only one bot instance is running\n",
            "ERROR:telegram.ext.dispatcher:No error handlers are registered, logging exception.\n",
            "Traceback (most recent call last):\n",
            "  File \"/usr/local/lib/python3.10/dist-packages/telegram/ext/updater.py\", line 646, in _network_loop_retry\n",
            "    if not action_cb():\n",
            "  File \"/usr/local/lib/python3.10/dist-packages/telegram/ext/updater.py\", line 597, in polling_action_cb\n",
            "    updates = self.bot.get_updates(\n",
            "  File \"/usr/local/lib/python3.10/dist-packages/telegram/ext/extbot.py\", line 222, in get_updates\n",
            "    updates = super().get_updates(\n",
            "  File \"/usr/local/lib/python3.10/dist-packages/telegram/bot.py\", line 130, in decorator\n",
            "    result = func(*args, **kwargs)\n",
            "  File \"/usr/local/lib/python3.10/dist-packages/telegram/bot.py\", line 2861, in get_updates\n",
            "    self._post(\n",
            "  File \"/usr/local/lib/python3.10/dist-packages/telegram/bot.py\", line 295, in _post\n",
            "    return self.request.post(\n",
            "  File \"/usr/local/lib/python3.10/dist-packages/telegram/utils/request.py\", line 356, in post\n",
            "    result = self._request_wrapper(\n",
            "  File \"/usr/local/lib/python3.10/dist-packages/telegram/utils/request.py\", line 283, in _request_wrapper\n",
            "    raise Conflict(message)\n",
            "telegram.error.Conflict: Conflict: terminated by other getUpdates request; make sure that only one bot instance is running\n",
            "ERROR:telegram.ext.updater:Error while getting Updates: Conflict: terminated by other getUpdates request; make sure that only one bot instance is running\n",
            "ERROR:telegram.ext.dispatcher:No error handlers are registered, logging exception.\n",
            "Traceback (most recent call last):\n",
            "  File \"/usr/local/lib/python3.10/dist-packages/telegram/ext/updater.py\", line 646, in _network_loop_retry\n",
            "    if not action_cb():\n",
            "  File \"/usr/local/lib/python3.10/dist-packages/telegram/ext/updater.py\", line 597, in polling_action_cb\n",
            "    updates = self.bot.get_updates(\n",
            "  File \"/usr/local/lib/python3.10/dist-packages/telegram/ext/extbot.py\", line 222, in get_updates\n",
            "    updates = super().get_updates(\n",
            "  File \"/usr/local/lib/python3.10/dist-packages/telegram/bot.py\", line 130, in decorator\n",
            "    result = func(*args, **kwargs)\n",
            "  File \"/usr/local/lib/python3.10/dist-packages/telegram/bot.py\", line 2861, in get_updates\n",
            "    self._post(\n",
            "  File \"/usr/local/lib/python3.10/dist-packages/telegram/bot.py\", line 295, in _post\n",
            "    return self.request.post(\n",
            "  File \"/usr/local/lib/python3.10/dist-packages/telegram/utils/request.py\", line 356, in post\n",
            "    result = self._request_wrapper(\n",
            "  File \"/usr/local/lib/python3.10/dist-packages/telegram/utils/request.py\", line 283, in _request_wrapper\n",
            "    raise Conflict(message)\n",
            "telegram.error.Conflict: Conflict: terminated by other getUpdates request; make sure that only one bot instance is running\n",
            "ERROR:telegram.ext.updater:Error while getting Updates: Conflict: terminated by other getUpdates request; make sure that only one bot instance is running\n",
            "ERROR:telegram.ext.dispatcher:No error handlers are registered, logging exception.\n",
            "Traceback (most recent call last):\n",
            "  File \"/usr/local/lib/python3.10/dist-packages/telegram/ext/updater.py\", line 646, in _network_loop_retry\n",
            "    if not action_cb():\n",
            "  File \"/usr/local/lib/python3.10/dist-packages/telegram/ext/updater.py\", line 597, in polling_action_cb\n",
            "    updates = self.bot.get_updates(\n",
            "  File \"/usr/local/lib/python3.10/dist-packages/telegram/ext/extbot.py\", line 222, in get_updates\n",
            "    updates = super().get_updates(\n",
            "  File \"/usr/local/lib/python3.10/dist-packages/telegram/bot.py\", line 130, in decorator\n",
            "    result = func(*args, **kwargs)\n",
            "  File \"/usr/local/lib/python3.10/dist-packages/telegram/bot.py\", line 2861, in get_updates\n",
            "    self._post(\n",
            "  File \"/usr/local/lib/python3.10/dist-packages/telegram/bot.py\", line 295, in _post\n",
            "    return self.request.post(\n",
            "  File \"/usr/local/lib/python3.10/dist-packages/telegram/utils/request.py\", line 356, in post\n",
            "    result = self._request_wrapper(\n",
            "  File \"/usr/local/lib/python3.10/dist-packages/telegram/utils/request.py\", line 283, in _request_wrapper\n",
            "    raise Conflict(message)\n",
            "telegram.error.Conflict: Conflict: terminated by other getUpdates request; make sure that only one bot instance is running\n",
            "ERROR:telegram.ext.updater:Error while getting Updates: Conflict: terminated by other getUpdates request; make sure that only one bot instance is running\n",
            "ERROR:telegram.ext.dispatcher:No error handlers are registered, logging exception.\n",
            "Traceback (most recent call last):\n",
            "  File \"/usr/local/lib/python3.10/dist-packages/telegram/ext/updater.py\", line 646, in _network_loop_retry\n",
            "    if not action_cb():\n",
            "  File \"/usr/local/lib/python3.10/dist-packages/telegram/ext/updater.py\", line 597, in polling_action_cb\n",
            "    updates = self.bot.get_updates(\n",
            "  File \"/usr/local/lib/python3.10/dist-packages/telegram/ext/extbot.py\", line 222, in get_updates\n",
            "    updates = super().get_updates(\n",
            "  File \"/usr/local/lib/python3.10/dist-packages/telegram/bot.py\", line 130, in decorator\n",
            "    result = func(*args, **kwargs)\n",
            "  File \"/usr/local/lib/python3.10/dist-packages/telegram/bot.py\", line 2861, in get_updates\n",
            "    self._post(\n",
            "  File \"/usr/local/lib/python3.10/dist-packages/telegram/bot.py\", line 295, in _post\n",
            "    return self.request.post(\n",
            "  File \"/usr/local/lib/python3.10/dist-packages/telegram/utils/request.py\", line 356, in post\n",
            "    result = self._request_wrapper(\n",
            "  File \"/usr/local/lib/python3.10/dist-packages/telegram/utils/request.py\", line 283, in _request_wrapper\n",
            "    raise Conflict(message)\n",
            "telegram.error.Conflict: Conflict: terminated by other getUpdates request; make sure that only one bot instance is running\n",
            "ERROR:telegram.ext.updater:Error while getting Updates: Conflict: terminated by other getUpdates request; make sure that only one bot instance is running\n",
            "ERROR:telegram.ext.dispatcher:No error handlers are registered, logging exception.\n",
            "Traceback (most recent call last):\n",
            "  File \"/usr/local/lib/python3.10/dist-packages/telegram/ext/updater.py\", line 646, in _network_loop_retry\n",
            "    if not action_cb():\n",
            "  File \"/usr/local/lib/python3.10/dist-packages/telegram/ext/updater.py\", line 597, in polling_action_cb\n",
            "    updates = self.bot.get_updates(\n",
            "  File \"/usr/local/lib/python3.10/dist-packages/telegram/ext/extbot.py\", line 222, in get_updates\n",
            "    updates = super().get_updates(\n",
            "  File \"/usr/local/lib/python3.10/dist-packages/telegram/bot.py\", line 130, in decorator\n",
            "    result = func(*args, **kwargs)\n",
            "  File \"/usr/local/lib/python3.10/dist-packages/telegram/bot.py\", line 2861, in get_updates\n",
            "    self._post(\n",
            "  File \"/usr/local/lib/python3.10/dist-packages/telegram/bot.py\", line 295, in _post\n",
            "    return self.request.post(\n",
            "  File \"/usr/local/lib/python3.10/dist-packages/telegram/utils/request.py\", line 356, in post\n",
            "    result = self._request_wrapper(\n",
            "  File \"/usr/local/lib/python3.10/dist-packages/telegram/utils/request.py\", line 283, in _request_wrapper\n",
            "    raise Conflict(message)\n",
            "telegram.error.Conflict: Conflict: terminated by other getUpdates request; make sure that only one bot instance is running\n",
            "ERROR:telegram.ext.updater:Error while getting Updates: Conflict: terminated by other getUpdates request; make sure that only one bot instance is running\n",
            "ERROR:telegram.ext.dispatcher:No error handlers are registered, logging exception.\n",
            "Traceback (most recent call last):\n",
            "  File \"/usr/local/lib/python3.10/dist-packages/telegram/ext/updater.py\", line 646, in _network_loop_retry\n",
            "    if not action_cb():\n",
            "  File \"/usr/local/lib/python3.10/dist-packages/telegram/ext/updater.py\", line 597, in polling_action_cb\n",
            "    updates = self.bot.get_updates(\n",
            "  File \"/usr/local/lib/python3.10/dist-packages/telegram/ext/extbot.py\", line 222, in get_updates\n",
            "    updates = super().get_updates(\n",
            "  File \"/usr/local/lib/python3.10/dist-packages/telegram/bot.py\", line 130, in decorator\n",
            "    result = func(*args, **kwargs)\n",
            "  File \"/usr/local/lib/python3.10/dist-packages/telegram/bot.py\", line 2861, in get_updates\n",
            "    self._post(\n",
            "  File \"/usr/local/lib/python3.10/dist-packages/telegram/bot.py\", line 295, in _post\n",
            "    return self.request.post(\n",
            "  File \"/usr/local/lib/python3.10/dist-packages/telegram/utils/request.py\", line 356, in post\n",
            "    result = self._request_wrapper(\n",
            "  File \"/usr/local/lib/python3.10/dist-packages/telegram/utils/request.py\", line 283, in _request_wrapper\n",
            "    raise Conflict(message)\n",
            "telegram.error.Conflict: Conflict: terminated by other getUpdates request; make sure that only one bot instance is running\n",
            "ERROR:telegram.ext.updater:Error while getting Updates: Conflict: terminated by other getUpdates request; make sure that only one bot instance is running\n",
            "ERROR:telegram.ext.dispatcher:No error handlers are registered, logging exception.\n",
            "Traceback (most recent call last):\n",
            "  File \"/usr/local/lib/python3.10/dist-packages/telegram/ext/updater.py\", line 646, in _network_loop_retry\n",
            "    if not action_cb():\n",
            "  File \"/usr/local/lib/python3.10/dist-packages/telegram/ext/updater.py\", line 597, in polling_action_cb\n",
            "    updates = self.bot.get_updates(\n",
            "  File \"/usr/local/lib/python3.10/dist-packages/telegram/ext/extbot.py\", line 222, in get_updates\n",
            "    updates = super().get_updates(\n",
            "  File \"/usr/local/lib/python3.10/dist-packages/telegram/bot.py\", line 130, in decorator\n",
            "    result = func(*args, **kwargs)\n",
            "  File \"/usr/local/lib/python3.10/dist-packages/telegram/bot.py\", line 2861, in get_updates\n",
            "    self._post(\n",
            "  File \"/usr/local/lib/python3.10/dist-packages/telegram/bot.py\", line 295, in _post\n",
            "    return self.request.post(\n",
            "  File \"/usr/local/lib/python3.10/dist-packages/telegram/utils/request.py\", line 356, in post\n",
            "    result = self._request_wrapper(\n",
            "  File \"/usr/local/lib/python3.10/dist-packages/telegram/utils/request.py\", line 283, in _request_wrapper\n",
            "    raise Conflict(message)\n",
            "telegram.error.Conflict: Conflict: terminated by other getUpdates request; make sure that only one bot instance is running\n",
            "ERROR:telegram.ext.updater:Error while getting Updates: Conflict: terminated by other getUpdates request; make sure that only one bot instance is running\n",
            "ERROR:telegram.ext.dispatcher:No error handlers are registered, logging exception.\n",
            "Traceback (most recent call last):\n",
            "  File \"/usr/local/lib/python3.10/dist-packages/telegram/ext/updater.py\", line 646, in _network_loop_retry\n",
            "    if not action_cb():\n",
            "  File \"/usr/local/lib/python3.10/dist-packages/telegram/ext/updater.py\", line 597, in polling_action_cb\n",
            "    updates = self.bot.get_updates(\n",
            "  File \"/usr/local/lib/python3.10/dist-packages/telegram/ext/extbot.py\", line 222, in get_updates\n",
            "    updates = super().get_updates(\n",
            "  File \"/usr/local/lib/python3.10/dist-packages/telegram/bot.py\", line 130, in decorator\n",
            "    result = func(*args, **kwargs)\n",
            "  File \"/usr/local/lib/python3.10/dist-packages/telegram/bot.py\", line 2861, in get_updates\n",
            "    self._post(\n",
            "  File \"/usr/local/lib/python3.10/dist-packages/telegram/bot.py\", line 295, in _post\n",
            "    return self.request.post(\n",
            "  File \"/usr/local/lib/python3.10/dist-packages/telegram/utils/request.py\", line 356, in post\n",
            "    result = self._request_wrapper(\n",
            "  File \"/usr/local/lib/python3.10/dist-packages/telegram/utils/request.py\", line 283, in _request_wrapper\n",
            "    raise Conflict(message)\n",
            "telegram.error.Conflict: Conflict: terminated by other getUpdates request; make sure that only one bot instance is running\n",
            "ERROR:telegram.ext.updater:Error while getting Updates: Conflict: terminated by other getUpdates request; make sure that only one bot instance is running\n",
            "ERROR:telegram.ext.dispatcher:No error handlers are registered, logging exception.\n",
            "Traceback (most recent call last):\n",
            "  File \"/usr/local/lib/python3.10/dist-packages/telegram/ext/updater.py\", line 646, in _network_loop_retry\n",
            "    if not action_cb():\n",
            "  File \"/usr/local/lib/python3.10/dist-packages/telegram/ext/updater.py\", line 597, in polling_action_cb\n",
            "    updates = self.bot.get_updates(\n",
            "  File \"/usr/local/lib/python3.10/dist-packages/telegram/ext/extbot.py\", line 222, in get_updates\n",
            "    updates = super().get_updates(\n",
            "  File \"/usr/local/lib/python3.10/dist-packages/telegram/bot.py\", line 130, in decorator\n",
            "    result = func(*args, **kwargs)\n",
            "  File \"/usr/local/lib/python3.10/dist-packages/telegram/bot.py\", line 2861, in get_updates\n",
            "    self._post(\n",
            "  File \"/usr/local/lib/python3.10/dist-packages/telegram/bot.py\", line 295, in _post\n",
            "    return self.request.post(\n",
            "  File \"/usr/local/lib/python3.10/dist-packages/telegram/utils/request.py\", line 356, in post\n",
            "    result = self._request_wrapper(\n",
            "  File \"/usr/local/lib/python3.10/dist-packages/telegram/utils/request.py\", line 283, in _request_wrapper\n",
            "    raise Conflict(message)\n",
            "telegram.error.Conflict: Conflict: terminated by other getUpdates request; make sure that only one bot instance is running\n",
            "ERROR:telegram.ext.updater:Error while getting Updates: Conflict: terminated by other getUpdates request; make sure that only one bot instance is running\n",
            "ERROR:telegram.ext.dispatcher:No error handlers are registered, logging exception.\n",
            "Traceback (most recent call last):\n",
            "  File \"/usr/local/lib/python3.10/dist-packages/telegram/ext/updater.py\", line 646, in _network_loop_retry\n",
            "    if not action_cb():\n",
            "  File \"/usr/local/lib/python3.10/dist-packages/telegram/ext/updater.py\", line 597, in polling_action_cb\n",
            "    updates = self.bot.get_updates(\n",
            "  File \"/usr/local/lib/python3.10/dist-packages/telegram/ext/extbot.py\", line 222, in get_updates\n",
            "    updates = super().get_updates(\n",
            "  File \"/usr/local/lib/python3.10/dist-packages/telegram/bot.py\", line 130, in decorator\n",
            "    result = func(*args, **kwargs)\n",
            "  File \"/usr/local/lib/python3.10/dist-packages/telegram/bot.py\", line 2861, in get_updates\n",
            "    self._post(\n",
            "  File \"/usr/local/lib/python3.10/dist-packages/telegram/bot.py\", line 295, in _post\n",
            "    return self.request.post(\n",
            "  File \"/usr/local/lib/python3.10/dist-packages/telegram/utils/request.py\", line 356, in post\n",
            "    result = self._request_wrapper(\n",
            "  File \"/usr/local/lib/python3.10/dist-packages/telegram/utils/request.py\", line 283, in _request_wrapper\n",
            "    raise Conflict(message)\n",
            "telegram.error.Conflict: Conflict: terminated by other getUpdates request; make sure that only one bot instance is running\n",
            "ERROR:telegram.ext.updater:Error while getting Updates: Conflict: terminated by other getUpdates request; make sure that only one bot instance is running\n",
            "ERROR:telegram.ext.dispatcher:No error handlers are registered, logging exception.\n",
            "Traceback (most recent call last):\n",
            "  File \"/usr/local/lib/python3.10/dist-packages/telegram/ext/updater.py\", line 646, in _network_loop_retry\n",
            "    if not action_cb():\n",
            "  File \"/usr/local/lib/python3.10/dist-packages/telegram/ext/updater.py\", line 597, in polling_action_cb\n",
            "    updates = self.bot.get_updates(\n",
            "  File \"/usr/local/lib/python3.10/dist-packages/telegram/ext/extbot.py\", line 222, in get_updates\n",
            "    updates = super().get_updates(\n",
            "  File \"/usr/local/lib/python3.10/dist-packages/telegram/bot.py\", line 130, in decorator\n",
            "    result = func(*args, **kwargs)\n",
            "  File \"/usr/local/lib/python3.10/dist-packages/telegram/bot.py\", line 2861, in get_updates\n",
            "    self._post(\n",
            "  File \"/usr/local/lib/python3.10/dist-packages/telegram/bot.py\", line 295, in _post\n",
            "    return self.request.post(\n",
            "  File \"/usr/local/lib/python3.10/dist-packages/telegram/utils/request.py\", line 356, in post\n",
            "    result = self._request_wrapper(\n",
            "  File \"/usr/local/lib/python3.10/dist-packages/telegram/utils/request.py\", line 283, in _request_wrapper\n",
            "    raise Conflict(message)\n",
            "telegram.error.Conflict: Conflict: terminated by other getUpdates request; make sure that only one bot instance is running\n",
            "ERROR:telegram.ext.updater:Error while getting Updates: Conflict: terminated by other getUpdates request; make sure that only one bot instance is running\n",
            "ERROR:telegram.ext.dispatcher:No error handlers are registered, logging exception.\n",
            "Traceback (most recent call last):\n",
            "  File \"/usr/local/lib/python3.10/dist-packages/telegram/ext/updater.py\", line 646, in _network_loop_retry\n",
            "    if not action_cb():\n",
            "  File \"/usr/local/lib/python3.10/dist-packages/telegram/ext/updater.py\", line 597, in polling_action_cb\n",
            "    updates = self.bot.get_updates(\n",
            "  File \"/usr/local/lib/python3.10/dist-packages/telegram/ext/extbot.py\", line 222, in get_updates\n",
            "    updates = super().get_updates(\n",
            "  File \"/usr/local/lib/python3.10/dist-packages/telegram/bot.py\", line 130, in decorator\n",
            "    result = func(*args, **kwargs)\n",
            "  File \"/usr/local/lib/python3.10/dist-packages/telegram/bot.py\", line 2861, in get_updates\n",
            "    self._post(\n",
            "  File \"/usr/local/lib/python3.10/dist-packages/telegram/bot.py\", line 295, in _post\n",
            "    return self.request.post(\n",
            "  File \"/usr/local/lib/python3.10/dist-packages/telegram/utils/request.py\", line 356, in post\n",
            "    result = self._request_wrapper(\n",
            "  File \"/usr/local/lib/python3.10/dist-packages/telegram/utils/request.py\", line 283, in _request_wrapper\n",
            "    raise Conflict(message)\n",
            "telegram.error.Conflict: Conflict: terminated by other getUpdates request; make sure that only one bot instance is running\n",
            "ERROR:telegram.ext.updater:Error while getting Updates: Conflict: terminated by other getUpdates request; make sure that only one bot instance is running\n",
            "ERROR:telegram.ext.dispatcher:No error handlers are registered, logging exception.\n",
            "Traceback (most recent call last):\n",
            "  File \"/usr/local/lib/python3.10/dist-packages/telegram/ext/updater.py\", line 646, in _network_loop_retry\n",
            "    if not action_cb():\n",
            "  File \"/usr/local/lib/python3.10/dist-packages/telegram/ext/updater.py\", line 597, in polling_action_cb\n",
            "    updates = self.bot.get_updates(\n",
            "  File \"/usr/local/lib/python3.10/dist-packages/telegram/ext/extbot.py\", line 222, in get_updates\n",
            "    updates = super().get_updates(\n",
            "  File \"/usr/local/lib/python3.10/dist-packages/telegram/bot.py\", line 130, in decorator\n",
            "    result = func(*args, **kwargs)\n",
            "  File \"/usr/local/lib/python3.10/dist-packages/telegram/bot.py\", line 2861, in get_updates\n",
            "    self._post(\n",
            "  File \"/usr/local/lib/python3.10/dist-packages/telegram/bot.py\", line 295, in _post\n",
            "    return self.request.post(\n",
            "  File \"/usr/local/lib/python3.10/dist-packages/telegram/utils/request.py\", line 356, in post\n",
            "    result = self._request_wrapper(\n",
            "  File \"/usr/local/lib/python3.10/dist-packages/telegram/utils/request.py\", line 283, in _request_wrapper\n",
            "    raise Conflict(message)\n",
            "telegram.error.Conflict: Conflict: terminated by other getUpdates request; make sure that only one bot instance is running\n",
            "ERROR:telegram.ext.updater:Error while getting Updates: Conflict: terminated by other getUpdates request; make sure that only one bot instance is running\n",
            "ERROR:telegram.ext.dispatcher:No error handlers are registered, logging exception.\n",
            "Traceback (most recent call last):\n",
            "  File \"/usr/local/lib/python3.10/dist-packages/telegram/ext/updater.py\", line 646, in _network_loop_retry\n",
            "    if not action_cb():\n",
            "  File \"/usr/local/lib/python3.10/dist-packages/telegram/ext/updater.py\", line 597, in polling_action_cb\n",
            "    updates = self.bot.get_updates(\n",
            "  File \"/usr/local/lib/python3.10/dist-packages/telegram/ext/extbot.py\", line 222, in get_updates\n",
            "    updates = super().get_updates(\n",
            "  File \"/usr/local/lib/python3.10/dist-packages/telegram/bot.py\", line 130, in decorator\n",
            "    result = func(*args, **kwargs)\n",
            "  File \"/usr/local/lib/python3.10/dist-packages/telegram/bot.py\", line 2861, in get_updates\n",
            "    self._post(\n",
            "  File \"/usr/local/lib/python3.10/dist-packages/telegram/bot.py\", line 295, in _post\n",
            "    return self.request.post(\n",
            "  File \"/usr/local/lib/python3.10/dist-packages/telegram/utils/request.py\", line 356, in post\n",
            "    result = self._request_wrapper(\n",
            "  File \"/usr/local/lib/python3.10/dist-packages/telegram/utils/request.py\", line 283, in _request_wrapper\n",
            "    raise Conflict(message)\n",
            "telegram.error.Conflict: Conflict: terminated by other getUpdates request; make sure that only one bot instance is running\n",
            "ERROR:telegram.ext.updater:Error while getting Updates: Conflict: terminated by other getUpdates request; make sure that only one bot instance is running\n",
            "ERROR:telegram.ext.dispatcher:No error handlers are registered, logging exception.\n",
            "Traceback (most recent call last):\n",
            "  File \"/usr/local/lib/python3.10/dist-packages/telegram/ext/updater.py\", line 646, in _network_loop_retry\n",
            "    if not action_cb():\n",
            "  File \"/usr/local/lib/python3.10/dist-packages/telegram/ext/updater.py\", line 597, in polling_action_cb\n",
            "    updates = self.bot.get_updates(\n",
            "  File \"/usr/local/lib/python3.10/dist-packages/telegram/ext/extbot.py\", line 222, in get_updates\n",
            "    updates = super().get_updates(\n",
            "  File \"/usr/local/lib/python3.10/dist-packages/telegram/bot.py\", line 130, in decorator\n",
            "    result = func(*args, **kwargs)\n",
            "  File \"/usr/local/lib/python3.10/dist-packages/telegram/bot.py\", line 2861, in get_updates\n",
            "    self._post(\n",
            "  File \"/usr/local/lib/python3.10/dist-packages/telegram/bot.py\", line 295, in _post\n",
            "    return self.request.post(\n",
            "  File \"/usr/local/lib/python3.10/dist-packages/telegram/utils/request.py\", line 356, in post\n",
            "    result = self._request_wrapper(\n",
            "  File \"/usr/local/lib/python3.10/dist-packages/telegram/utils/request.py\", line 283, in _request_wrapper\n",
            "    raise Conflict(message)\n",
            "telegram.error.Conflict: Conflict: terminated by other getUpdates request; make sure that only one bot instance is running\n",
            "ERROR:telegram.ext.updater:Error while getting Updates: Conflict: terminated by other getUpdates request; make sure that only one bot instance is running\n",
            "ERROR:telegram.ext.dispatcher:No error handlers are registered, logging exception.\n",
            "Traceback (most recent call last):\n",
            "  File \"/usr/local/lib/python3.10/dist-packages/telegram/ext/updater.py\", line 646, in _network_loop_retry\n",
            "    if not action_cb():\n",
            "  File \"/usr/local/lib/python3.10/dist-packages/telegram/ext/updater.py\", line 597, in polling_action_cb\n",
            "    updates = self.bot.get_updates(\n",
            "  File \"/usr/local/lib/python3.10/dist-packages/telegram/ext/extbot.py\", line 222, in get_updates\n",
            "    updates = super().get_updates(\n",
            "  File \"/usr/local/lib/python3.10/dist-packages/telegram/bot.py\", line 130, in decorator\n",
            "    result = func(*args, **kwargs)\n",
            "  File \"/usr/local/lib/python3.10/dist-packages/telegram/bot.py\", line 2861, in get_updates\n",
            "    self._post(\n",
            "  File \"/usr/local/lib/python3.10/dist-packages/telegram/bot.py\", line 295, in _post\n",
            "    return self.request.post(\n",
            "  File \"/usr/local/lib/python3.10/dist-packages/telegram/utils/request.py\", line 356, in post\n",
            "    result = self._request_wrapper(\n",
            "  File \"/usr/local/lib/python3.10/dist-packages/telegram/utils/request.py\", line 283, in _request_wrapper\n",
            "    raise Conflict(message)\n",
            "telegram.error.Conflict: Conflict: terminated by other getUpdates request; make sure that only one bot instance is running\n",
            "ERROR:telegram.ext.updater:Error while getting Updates: Conflict: terminated by other getUpdates request; make sure that only one bot instance is running\n",
            "ERROR:telegram.ext.dispatcher:No error handlers are registered, logging exception.\n",
            "Traceback (most recent call last):\n",
            "  File \"/usr/local/lib/python3.10/dist-packages/telegram/ext/updater.py\", line 646, in _network_loop_retry\n",
            "    if not action_cb():\n",
            "  File \"/usr/local/lib/python3.10/dist-packages/telegram/ext/updater.py\", line 597, in polling_action_cb\n",
            "    updates = self.bot.get_updates(\n",
            "  File \"/usr/local/lib/python3.10/dist-packages/telegram/ext/extbot.py\", line 222, in get_updates\n",
            "    updates = super().get_updates(\n",
            "  File \"/usr/local/lib/python3.10/dist-packages/telegram/bot.py\", line 130, in decorator\n",
            "    result = func(*args, **kwargs)\n",
            "  File \"/usr/local/lib/python3.10/dist-packages/telegram/bot.py\", line 2861, in get_updates\n",
            "    self._post(\n",
            "  File \"/usr/local/lib/python3.10/dist-packages/telegram/bot.py\", line 295, in _post\n",
            "    return self.request.post(\n",
            "  File \"/usr/local/lib/python3.10/dist-packages/telegram/utils/request.py\", line 356, in post\n",
            "    result = self._request_wrapper(\n",
            "  File \"/usr/local/lib/python3.10/dist-packages/telegram/utils/request.py\", line 283, in _request_wrapper\n",
            "    raise Conflict(message)\n",
            "telegram.error.Conflict: Conflict: terminated by other getUpdates request; make sure that only one bot instance is running\n",
            "ERROR:telegram.ext.updater:Error while getting Updates: Conflict: terminated by other getUpdates request; make sure that only one bot instance is running\n",
            "ERROR:telegram.ext.dispatcher:No error handlers are registered, logging exception.\n",
            "Traceback (most recent call last):\n",
            "  File \"/usr/local/lib/python3.10/dist-packages/telegram/ext/updater.py\", line 646, in _network_loop_retry\n",
            "    if not action_cb():\n",
            "  File \"/usr/local/lib/python3.10/dist-packages/telegram/ext/updater.py\", line 597, in polling_action_cb\n",
            "    updates = self.bot.get_updates(\n",
            "  File \"/usr/local/lib/python3.10/dist-packages/telegram/ext/extbot.py\", line 222, in get_updates\n",
            "    updates = super().get_updates(\n",
            "  File \"/usr/local/lib/python3.10/dist-packages/telegram/bot.py\", line 130, in decorator\n",
            "    result = func(*args, **kwargs)\n",
            "  File \"/usr/local/lib/python3.10/dist-packages/telegram/bot.py\", line 2861, in get_updates\n",
            "    self._post(\n",
            "  File \"/usr/local/lib/python3.10/dist-packages/telegram/bot.py\", line 295, in _post\n",
            "    return self.request.post(\n",
            "  File \"/usr/local/lib/python3.10/dist-packages/telegram/utils/request.py\", line 356, in post\n",
            "    result = self._request_wrapper(\n",
            "  File \"/usr/local/lib/python3.10/dist-packages/telegram/utils/request.py\", line 283, in _request_wrapper\n",
            "    raise Conflict(message)\n",
            "telegram.error.Conflict: Conflict: terminated by other getUpdates request; make sure that only one bot instance is running\n",
            "ERROR:telegram.ext.updater:Error while getting Updates: Conflict: terminated by other getUpdates request; make sure that only one bot instance is running\n",
            "ERROR:telegram.ext.dispatcher:No error handlers are registered, logging exception.\n",
            "Traceback (most recent call last):\n",
            "  File \"/usr/local/lib/python3.10/dist-packages/telegram/ext/updater.py\", line 646, in _network_loop_retry\n",
            "    if not action_cb():\n",
            "  File \"/usr/local/lib/python3.10/dist-packages/telegram/ext/updater.py\", line 597, in polling_action_cb\n",
            "    updates = self.bot.get_updates(\n",
            "  File \"/usr/local/lib/python3.10/dist-packages/telegram/ext/extbot.py\", line 222, in get_updates\n",
            "    updates = super().get_updates(\n",
            "  File \"/usr/local/lib/python3.10/dist-packages/telegram/bot.py\", line 130, in decorator\n",
            "    result = func(*args, **kwargs)\n",
            "  File \"/usr/local/lib/python3.10/dist-packages/telegram/bot.py\", line 2861, in get_updates\n",
            "    self._post(\n",
            "  File \"/usr/local/lib/python3.10/dist-packages/telegram/bot.py\", line 295, in _post\n",
            "    return self.request.post(\n",
            "  File \"/usr/local/lib/python3.10/dist-packages/telegram/utils/request.py\", line 356, in post\n",
            "    result = self._request_wrapper(\n",
            "  File \"/usr/local/lib/python3.10/dist-packages/telegram/utils/request.py\", line 283, in _request_wrapper\n",
            "    raise Conflict(message)\n",
            "telegram.error.Conflict: Conflict: terminated by other getUpdates request; make sure that only one bot instance is running\n",
            "ERROR:telegram.ext.updater:Error while getting Updates: Conflict: terminated by other getUpdates request; make sure that only one bot instance is running\n",
            "ERROR:telegram.ext.dispatcher:No error handlers are registered, logging exception.\n",
            "Traceback (most recent call last):\n",
            "  File \"/usr/local/lib/python3.10/dist-packages/telegram/ext/updater.py\", line 646, in _network_loop_retry\n",
            "    if not action_cb():\n",
            "  File \"/usr/local/lib/python3.10/dist-packages/telegram/ext/updater.py\", line 597, in polling_action_cb\n",
            "    updates = self.bot.get_updates(\n",
            "  File \"/usr/local/lib/python3.10/dist-packages/telegram/ext/extbot.py\", line 222, in get_updates\n",
            "    updates = super().get_updates(\n",
            "  File \"/usr/local/lib/python3.10/dist-packages/telegram/bot.py\", line 130, in decorator\n",
            "    result = func(*args, **kwargs)\n",
            "  File \"/usr/local/lib/python3.10/dist-packages/telegram/bot.py\", line 2861, in get_updates\n",
            "    self._post(\n",
            "  File \"/usr/local/lib/python3.10/dist-packages/telegram/bot.py\", line 295, in _post\n",
            "    return self.request.post(\n",
            "  File \"/usr/local/lib/python3.10/dist-packages/telegram/utils/request.py\", line 356, in post\n",
            "    result = self._request_wrapper(\n",
            "  File \"/usr/local/lib/python3.10/dist-packages/telegram/utils/request.py\", line 283, in _request_wrapper\n",
            "    raise Conflict(message)\n",
            "telegram.error.Conflict: Conflict: terminated by other getUpdates request; make sure that only one bot instance is running\n",
            "ERROR:telegram.ext.updater:Error while getting Updates: Conflict: terminated by other getUpdates request; make sure that only one bot instance is running\n",
            "ERROR:telegram.ext.dispatcher:No error handlers are registered, logging exception.\n",
            "Traceback (most recent call last):\n",
            "  File \"/usr/local/lib/python3.10/dist-packages/telegram/ext/updater.py\", line 646, in _network_loop_retry\n",
            "    if not action_cb():\n",
            "  File \"/usr/local/lib/python3.10/dist-packages/telegram/ext/updater.py\", line 597, in polling_action_cb\n",
            "    updates = self.bot.get_updates(\n",
            "  File \"/usr/local/lib/python3.10/dist-packages/telegram/ext/extbot.py\", line 222, in get_updates\n",
            "    updates = super().get_updates(\n",
            "  File \"/usr/local/lib/python3.10/dist-packages/telegram/bot.py\", line 130, in decorator\n",
            "    result = func(*args, **kwargs)\n",
            "  File \"/usr/local/lib/python3.10/dist-packages/telegram/bot.py\", line 2861, in get_updates\n",
            "    self._post(\n",
            "  File \"/usr/local/lib/python3.10/dist-packages/telegram/bot.py\", line 295, in _post\n",
            "    return self.request.post(\n",
            "  File \"/usr/local/lib/python3.10/dist-packages/telegram/utils/request.py\", line 356, in post\n",
            "    result = self._request_wrapper(\n",
            "  File \"/usr/local/lib/python3.10/dist-packages/telegram/utils/request.py\", line 283, in _request_wrapper\n",
            "    raise Conflict(message)\n",
            "telegram.error.Conflict: Conflict: terminated by other getUpdates request; make sure that only one bot instance is running\n",
            "ERROR:telegram.ext.updater:Error while getting Updates: Conflict: terminated by other getUpdates request; make sure that only one bot instance is running\n",
            "ERROR:telegram.ext.dispatcher:No error handlers are registered, logging exception.\n",
            "Traceback (most recent call last):\n",
            "  File \"/usr/local/lib/python3.10/dist-packages/telegram/ext/updater.py\", line 646, in _network_loop_retry\n",
            "    if not action_cb():\n",
            "  File \"/usr/local/lib/python3.10/dist-packages/telegram/ext/updater.py\", line 597, in polling_action_cb\n",
            "    updates = self.bot.get_updates(\n",
            "  File \"/usr/local/lib/python3.10/dist-packages/telegram/ext/extbot.py\", line 222, in get_updates\n",
            "    updates = super().get_updates(\n",
            "  File \"/usr/local/lib/python3.10/dist-packages/telegram/bot.py\", line 130, in decorator\n",
            "    result = func(*args, **kwargs)\n",
            "  File \"/usr/local/lib/python3.10/dist-packages/telegram/bot.py\", line 2861, in get_updates\n",
            "    self._post(\n",
            "  File \"/usr/local/lib/python3.10/dist-packages/telegram/bot.py\", line 295, in _post\n",
            "    return self.request.post(\n",
            "  File \"/usr/local/lib/python3.10/dist-packages/telegram/utils/request.py\", line 356, in post\n",
            "    result = self._request_wrapper(\n",
            "  File \"/usr/local/lib/python3.10/dist-packages/telegram/utils/request.py\", line 283, in _request_wrapper\n",
            "    raise Conflict(message)\n",
            "telegram.error.Conflict: Conflict: terminated by other getUpdates request; make sure that only one bot instance is running\n",
            "ERROR:telegram.ext.updater:Error while getting Updates: Conflict: terminated by other getUpdates request; make sure that only one bot instance is running\n",
            "ERROR:telegram.ext.dispatcher:No error handlers are registered, logging exception.\n",
            "Traceback (most recent call last):\n",
            "  File \"/usr/local/lib/python3.10/dist-packages/telegram/ext/updater.py\", line 646, in _network_loop_retry\n",
            "    if not action_cb():\n",
            "  File \"/usr/local/lib/python3.10/dist-packages/telegram/ext/updater.py\", line 597, in polling_action_cb\n",
            "    updates = self.bot.get_updates(\n",
            "  File \"/usr/local/lib/python3.10/dist-packages/telegram/ext/extbot.py\", line 222, in get_updates\n",
            "    updates = super().get_updates(\n",
            "  File \"/usr/local/lib/python3.10/dist-packages/telegram/bot.py\", line 130, in decorator\n",
            "    result = func(*args, **kwargs)\n",
            "  File \"/usr/local/lib/python3.10/dist-packages/telegram/bot.py\", line 2861, in get_updates\n",
            "    self._post(\n",
            "  File \"/usr/local/lib/python3.10/dist-packages/telegram/bot.py\", line 295, in _post\n",
            "    return self.request.post(\n",
            "  File \"/usr/local/lib/python3.10/dist-packages/telegram/utils/request.py\", line 356, in post\n",
            "    result = self._request_wrapper(\n",
            "  File \"/usr/local/lib/python3.10/dist-packages/telegram/utils/request.py\", line 283, in _request_wrapper\n",
            "    raise Conflict(message)\n",
            "telegram.error.Conflict: Conflict: terminated by other getUpdates request; make sure that only one bot instance is running\n",
            "ERROR:telegram.ext.updater:Error while getting Updates: Conflict: terminated by other getUpdates request; make sure that only one bot instance is running\n",
            "ERROR:telegram.ext.dispatcher:No error handlers are registered, logging exception.\n",
            "Traceback (most recent call last):\n",
            "  File \"/usr/local/lib/python3.10/dist-packages/telegram/ext/updater.py\", line 646, in _network_loop_retry\n",
            "    if not action_cb():\n",
            "  File \"/usr/local/lib/python3.10/dist-packages/telegram/ext/updater.py\", line 597, in polling_action_cb\n",
            "    updates = self.bot.get_updates(\n",
            "  File \"/usr/local/lib/python3.10/dist-packages/telegram/ext/extbot.py\", line 222, in get_updates\n",
            "    updates = super().get_updates(\n",
            "  File \"/usr/local/lib/python3.10/dist-packages/telegram/bot.py\", line 130, in decorator\n",
            "    result = func(*args, **kwargs)\n",
            "  File \"/usr/local/lib/python3.10/dist-packages/telegram/bot.py\", line 2861, in get_updates\n",
            "    self._post(\n",
            "  File \"/usr/local/lib/python3.10/dist-packages/telegram/bot.py\", line 295, in _post\n",
            "    return self.request.post(\n",
            "  File \"/usr/local/lib/python3.10/dist-packages/telegram/utils/request.py\", line 356, in post\n",
            "    result = self._request_wrapper(\n",
            "  File \"/usr/local/lib/python3.10/dist-packages/telegram/utils/request.py\", line 283, in _request_wrapper\n",
            "    raise Conflict(message)\n",
            "telegram.error.Conflict: Conflict: terminated by other getUpdates request; make sure that only one bot instance is running\n",
            "ERROR:telegram.ext.updater:Error while getting Updates: Conflict: terminated by other getUpdates request; make sure that only one bot instance is running\n",
            "ERROR:telegram.ext.dispatcher:No error handlers are registered, logging exception.\n",
            "Traceback (most recent call last):\n",
            "  File \"/usr/local/lib/python3.10/dist-packages/telegram/ext/updater.py\", line 646, in _network_loop_retry\n",
            "    if not action_cb():\n",
            "  File \"/usr/local/lib/python3.10/dist-packages/telegram/ext/updater.py\", line 597, in polling_action_cb\n",
            "    updates = self.bot.get_updates(\n",
            "  File \"/usr/local/lib/python3.10/dist-packages/telegram/ext/extbot.py\", line 222, in get_updates\n",
            "    updates = super().get_updates(\n",
            "  File \"/usr/local/lib/python3.10/dist-packages/telegram/bot.py\", line 130, in decorator\n",
            "    result = func(*args, **kwargs)\n",
            "  File \"/usr/local/lib/python3.10/dist-packages/telegram/bot.py\", line 2861, in get_updates\n",
            "    self._post(\n",
            "  File \"/usr/local/lib/python3.10/dist-packages/telegram/bot.py\", line 295, in _post\n",
            "    return self.request.post(\n",
            "  File \"/usr/local/lib/python3.10/dist-packages/telegram/utils/request.py\", line 356, in post\n",
            "    result = self._request_wrapper(\n",
            "  File \"/usr/local/lib/python3.10/dist-packages/telegram/utils/request.py\", line 283, in _request_wrapper\n",
            "    raise Conflict(message)\n",
            "telegram.error.Conflict: Conflict: terminated by other getUpdates request; make sure that only one bot instance is running\n",
            "ERROR:telegram.ext.updater:Error while getting Updates: Conflict: terminated by other getUpdates request; make sure that only one bot instance is running\n",
            "ERROR:telegram.ext.dispatcher:No error handlers are registered, logging exception.\n",
            "Traceback (most recent call last):\n",
            "  File \"/usr/local/lib/python3.10/dist-packages/telegram/ext/updater.py\", line 646, in _network_loop_retry\n",
            "    if not action_cb():\n",
            "  File \"/usr/local/lib/python3.10/dist-packages/telegram/ext/updater.py\", line 597, in polling_action_cb\n",
            "    updates = self.bot.get_updates(\n",
            "  File \"/usr/local/lib/python3.10/dist-packages/telegram/ext/extbot.py\", line 222, in get_updates\n",
            "    updates = super().get_updates(\n",
            "  File \"/usr/local/lib/python3.10/dist-packages/telegram/bot.py\", line 130, in decorator\n",
            "    result = func(*args, **kwargs)\n",
            "  File \"/usr/local/lib/python3.10/dist-packages/telegram/bot.py\", line 2861, in get_updates\n",
            "    self._post(\n",
            "  File \"/usr/local/lib/python3.10/dist-packages/telegram/bot.py\", line 295, in _post\n",
            "    return self.request.post(\n",
            "  File \"/usr/local/lib/python3.10/dist-packages/telegram/utils/request.py\", line 356, in post\n",
            "    result = self._request_wrapper(\n",
            "  File \"/usr/local/lib/python3.10/dist-packages/telegram/utils/request.py\", line 283, in _request_wrapper\n",
            "    raise Conflict(message)\n",
            "telegram.error.Conflict: Conflict: terminated by other getUpdates request; make sure that only one bot instance is running\n",
            "ERROR:telegram.ext.updater:Error while getting Updates: Conflict: terminated by other getUpdates request; make sure that only one bot instance is running\n",
            "ERROR:telegram.ext.dispatcher:No error handlers are registered, logging exception.\n",
            "Traceback (most recent call last):\n",
            "  File \"/usr/local/lib/python3.10/dist-packages/telegram/ext/updater.py\", line 646, in _network_loop_retry\n",
            "    if not action_cb():\n",
            "  File \"/usr/local/lib/python3.10/dist-packages/telegram/ext/updater.py\", line 597, in polling_action_cb\n",
            "    updates = self.bot.get_updates(\n",
            "  File \"/usr/local/lib/python3.10/dist-packages/telegram/ext/extbot.py\", line 222, in get_updates\n",
            "    updates = super().get_updates(\n",
            "  File \"/usr/local/lib/python3.10/dist-packages/telegram/bot.py\", line 130, in decorator\n",
            "    result = func(*args, **kwargs)\n",
            "  File \"/usr/local/lib/python3.10/dist-packages/telegram/bot.py\", line 2861, in get_updates\n",
            "    self._post(\n",
            "  File \"/usr/local/lib/python3.10/dist-packages/telegram/bot.py\", line 295, in _post\n",
            "    return self.request.post(\n",
            "  File \"/usr/local/lib/python3.10/dist-packages/telegram/utils/request.py\", line 356, in post\n",
            "    result = self._request_wrapper(\n",
            "  File \"/usr/local/lib/python3.10/dist-packages/telegram/utils/request.py\", line 283, in _request_wrapper\n",
            "    raise Conflict(message)\n",
            "telegram.error.Conflict: Conflict: terminated by other getUpdates request; make sure that only one bot instance is running\n",
            "ERROR:telegram.ext.updater:Error while getting Updates: Conflict: terminated by other getUpdates request; make sure that only one bot instance is running\n",
            "ERROR:telegram.ext.dispatcher:No error handlers are registered, logging exception.\n",
            "Traceback (most recent call last):\n",
            "  File \"/usr/local/lib/python3.10/dist-packages/telegram/ext/updater.py\", line 646, in _network_loop_retry\n",
            "    if not action_cb():\n",
            "  File \"/usr/local/lib/python3.10/dist-packages/telegram/ext/updater.py\", line 597, in polling_action_cb\n",
            "    updates = self.bot.get_updates(\n",
            "  File \"/usr/local/lib/python3.10/dist-packages/telegram/ext/extbot.py\", line 222, in get_updates\n",
            "    updates = super().get_updates(\n",
            "  File \"/usr/local/lib/python3.10/dist-packages/telegram/bot.py\", line 130, in decorator\n",
            "    result = func(*args, **kwargs)\n",
            "  File \"/usr/local/lib/python3.10/dist-packages/telegram/bot.py\", line 2861, in get_updates\n",
            "    self._post(\n",
            "  File \"/usr/local/lib/python3.10/dist-packages/telegram/bot.py\", line 295, in _post\n",
            "    return self.request.post(\n",
            "  File \"/usr/local/lib/python3.10/dist-packages/telegram/utils/request.py\", line 356, in post\n",
            "    result = self._request_wrapper(\n",
            "  File \"/usr/local/lib/python3.10/dist-packages/telegram/utils/request.py\", line 283, in _request_wrapper\n",
            "    raise Conflict(message)\n",
            "telegram.error.Conflict: Conflict: terminated by other getUpdates request; make sure that only one bot instance is running\n",
            "ERROR:telegram.ext.updater:Error while getting Updates: Conflict: terminated by other getUpdates request; make sure that only one bot instance is running\n",
            "ERROR:telegram.ext.dispatcher:No error handlers are registered, logging exception.\n",
            "Traceback (most recent call last):\n",
            "  File \"/usr/local/lib/python3.10/dist-packages/telegram/ext/updater.py\", line 646, in _network_loop_retry\n",
            "    if not action_cb():\n",
            "  File \"/usr/local/lib/python3.10/dist-packages/telegram/ext/updater.py\", line 597, in polling_action_cb\n",
            "    updates = self.bot.get_updates(\n",
            "  File \"/usr/local/lib/python3.10/dist-packages/telegram/ext/extbot.py\", line 222, in get_updates\n",
            "    updates = super().get_updates(\n",
            "  File \"/usr/local/lib/python3.10/dist-packages/telegram/bot.py\", line 130, in decorator\n",
            "    result = func(*args, **kwargs)\n",
            "  File \"/usr/local/lib/python3.10/dist-packages/telegram/bot.py\", line 2861, in get_updates\n",
            "    self._post(\n",
            "  File \"/usr/local/lib/python3.10/dist-packages/telegram/bot.py\", line 295, in _post\n",
            "    return self.request.post(\n",
            "  File \"/usr/local/lib/python3.10/dist-packages/telegram/utils/request.py\", line 356, in post\n",
            "    result = self._request_wrapper(\n",
            "  File \"/usr/local/lib/python3.10/dist-packages/telegram/utils/request.py\", line 283, in _request_wrapper\n",
            "    raise Conflict(message)\n",
            "telegram.error.Conflict: Conflict: terminated by other getUpdates request; make sure that only one bot instance is running\n",
            "ERROR:telegram.ext.updater:Error while getting Updates: Conflict: terminated by other getUpdates request; make sure that only one bot instance is running\n",
            "ERROR:telegram.ext.dispatcher:No error handlers are registered, logging exception.\n",
            "Traceback (most recent call last):\n",
            "  File \"/usr/local/lib/python3.10/dist-packages/telegram/ext/updater.py\", line 646, in _network_loop_retry\n",
            "    if not action_cb():\n",
            "  File \"/usr/local/lib/python3.10/dist-packages/telegram/ext/updater.py\", line 597, in polling_action_cb\n",
            "    updates = self.bot.get_updates(\n",
            "  File \"/usr/local/lib/python3.10/dist-packages/telegram/ext/extbot.py\", line 222, in get_updates\n",
            "    updates = super().get_updates(\n",
            "  File \"/usr/local/lib/python3.10/dist-packages/telegram/bot.py\", line 130, in decorator\n",
            "    result = func(*args, **kwargs)\n",
            "  File \"/usr/local/lib/python3.10/dist-packages/telegram/bot.py\", line 2861, in get_updates\n",
            "    self._post(\n",
            "  File \"/usr/local/lib/python3.10/dist-packages/telegram/bot.py\", line 295, in _post\n",
            "    return self.request.post(\n",
            "  File \"/usr/local/lib/python3.10/dist-packages/telegram/utils/request.py\", line 356, in post\n",
            "    result = self._request_wrapper(\n",
            "  File \"/usr/local/lib/python3.10/dist-packages/telegram/utils/request.py\", line 283, in _request_wrapper\n",
            "    raise Conflict(message)\n",
            "telegram.error.Conflict: Conflict: terminated by other getUpdates request; make sure that only one bot instance is running\n",
            "ERROR:telegram.ext.updater:Error while getting Updates: Conflict: terminated by other getUpdates request; make sure that only one bot instance is running\n",
            "ERROR:telegram.ext.dispatcher:No error handlers are registered, logging exception.\n",
            "Traceback (most recent call last):\n",
            "  File \"/usr/local/lib/python3.10/dist-packages/telegram/ext/updater.py\", line 646, in _network_loop_retry\n",
            "    if not action_cb():\n",
            "  File \"/usr/local/lib/python3.10/dist-packages/telegram/ext/updater.py\", line 597, in polling_action_cb\n",
            "    updates = self.bot.get_updates(\n",
            "  File \"/usr/local/lib/python3.10/dist-packages/telegram/ext/extbot.py\", line 222, in get_updates\n",
            "    updates = super().get_updates(\n",
            "  File \"/usr/local/lib/python3.10/dist-packages/telegram/bot.py\", line 130, in decorator\n",
            "    result = func(*args, **kwargs)\n",
            "  File \"/usr/local/lib/python3.10/dist-packages/telegram/bot.py\", line 2861, in get_updates\n",
            "    self._post(\n",
            "  File \"/usr/local/lib/python3.10/dist-packages/telegram/bot.py\", line 295, in _post\n",
            "    return self.request.post(\n",
            "  File \"/usr/local/lib/python3.10/dist-packages/telegram/utils/request.py\", line 356, in post\n",
            "    result = self._request_wrapper(\n",
            "  File \"/usr/local/lib/python3.10/dist-packages/telegram/utils/request.py\", line 283, in _request_wrapper\n",
            "    raise Conflict(message)\n",
            "telegram.error.Conflict: Conflict: terminated by other getUpdates request; make sure that only one bot instance is running\n",
            "ERROR:telegram.ext.updater:Error while getting Updates: Conflict: terminated by other getUpdates request; make sure that only one bot instance is running\n",
            "ERROR:telegram.ext.dispatcher:No error handlers are registered, logging exception.\n",
            "Traceback (most recent call last):\n",
            "  File \"/usr/local/lib/python3.10/dist-packages/telegram/ext/updater.py\", line 646, in _network_loop_retry\n",
            "    if not action_cb():\n",
            "  File \"/usr/local/lib/python3.10/dist-packages/telegram/ext/updater.py\", line 597, in polling_action_cb\n",
            "    updates = self.bot.get_updates(\n",
            "  File \"/usr/local/lib/python3.10/dist-packages/telegram/ext/extbot.py\", line 222, in get_updates\n",
            "    updates = super().get_updates(\n",
            "  File \"/usr/local/lib/python3.10/dist-packages/telegram/bot.py\", line 130, in decorator\n",
            "    result = func(*args, **kwargs)\n",
            "  File \"/usr/local/lib/python3.10/dist-packages/telegram/bot.py\", line 2861, in get_updates\n",
            "    self._post(\n",
            "  File \"/usr/local/lib/python3.10/dist-packages/telegram/bot.py\", line 295, in _post\n",
            "    return self.request.post(\n",
            "  File \"/usr/local/lib/python3.10/dist-packages/telegram/utils/request.py\", line 356, in post\n",
            "    result = self._request_wrapper(\n",
            "  File \"/usr/local/lib/python3.10/dist-packages/telegram/utils/request.py\", line 283, in _request_wrapper\n",
            "    raise Conflict(message)\n",
            "telegram.error.Conflict: Conflict: terminated by other getUpdates request; make sure that only one bot instance is running\n",
            "ERROR:telegram.ext.updater:Error while getting Updates: Conflict: terminated by other getUpdates request; make sure that only one bot instance is running\n",
            "ERROR:telegram.ext.dispatcher:No error handlers are registered, logging exception.\n",
            "Traceback (most recent call last):\n",
            "  File \"/usr/local/lib/python3.10/dist-packages/telegram/ext/updater.py\", line 646, in _network_loop_retry\n",
            "    if not action_cb():\n",
            "  File \"/usr/local/lib/python3.10/dist-packages/telegram/ext/updater.py\", line 597, in polling_action_cb\n",
            "    updates = self.bot.get_updates(\n",
            "  File \"/usr/local/lib/python3.10/dist-packages/telegram/ext/extbot.py\", line 222, in get_updates\n",
            "    updates = super().get_updates(\n",
            "  File \"/usr/local/lib/python3.10/dist-packages/telegram/bot.py\", line 130, in decorator\n",
            "    result = func(*args, **kwargs)\n",
            "  File \"/usr/local/lib/python3.10/dist-packages/telegram/bot.py\", line 2861, in get_updates\n",
            "    self._post(\n",
            "  File \"/usr/local/lib/python3.10/dist-packages/telegram/bot.py\", line 295, in _post\n",
            "    return self.request.post(\n",
            "  File \"/usr/local/lib/python3.10/dist-packages/telegram/utils/request.py\", line 356, in post\n",
            "    result = self._request_wrapper(\n",
            "  File \"/usr/local/lib/python3.10/dist-packages/telegram/utils/request.py\", line 283, in _request_wrapper\n",
            "    raise Conflict(message)\n",
            "telegram.error.Conflict: Conflict: terminated by other getUpdates request; make sure that only one bot instance is running\n",
            "ERROR:telegram.ext.updater:Error while getting Updates: Conflict: terminated by other getUpdates request; make sure that only one bot instance is running\n",
            "ERROR:telegram.ext.dispatcher:No error handlers are registered, logging exception.\n",
            "Traceback (most recent call last):\n",
            "  File \"/usr/local/lib/python3.10/dist-packages/telegram/ext/updater.py\", line 646, in _network_loop_retry\n",
            "    if not action_cb():\n",
            "  File \"/usr/local/lib/python3.10/dist-packages/telegram/ext/updater.py\", line 597, in polling_action_cb\n",
            "    updates = self.bot.get_updates(\n",
            "  File \"/usr/local/lib/python3.10/dist-packages/telegram/ext/extbot.py\", line 222, in get_updates\n",
            "    updates = super().get_updates(\n",
            "  File \"/usr/local/lib/python3.10/dist-packages/telegram/bot.py\", line 130, in decorator\n",
            "    result = func(*args, **kwargs)\n",
            "  File \"/usr/local/lib/python3.10/dist-packages/telegram/bot.py\", line 2861, in get_updates\n",
            "    self._post(\n",
            "  File \"/usr/local/lib/python3.10/dist-packages/telegram/bot.py\", line 295, in _post\n",
            "    return self.request.post(\n",
            "  File \"/usr/local/lib/python3.10/dist-packages/telegram/utils/request.py\", line 356, in post\n",
            "    result = self._request_wrapper(\n",
            "  File \"/usr/local/lib/python3.10/dist-packages/telegram/utils/request.py\", line 283, in _request_wrapper\n",
            "    raise Conflict(message)\n",
            "telegram.error.Conflict: Conflict: terminated by other getUpdates request; make sure that only one bot instance is running\n",
            "ERROR:telegram.ext.updater:Error while getting Updates: Conflict: terminated by other getUpdates request; make sure that only one bot instance is running\n",
            "ERROR:telegram.ext.dispatcher:No error handlers are registered, logging exception.\n",
            "Traceback (most recent call last):\n",
            "  File \"/usr/local/lib/python3.10/dist-packages/telegram/ext/updater.py\", line 646, in _network_loop_retry\n",
            "    if not action_cb():\n",
            "  File \"/usr/local/lib/python3.10/dist-packages/telegram/ext/updater.py\", line 597, in polling_action_cb\n",
            "    updates = self.bot.get_updates(\n",
            "  File \"/usr/local/lib/python3.10/dist-packages/telegram/ext/extbot.py\", line 222, in get_updates\n",
            "    updates = super().get_updates(\n",
            "  File \"/usr/local/lib/python3.10/dist-packages/telegram/bot.py\", line 130, in decorator\n",
            "    result = func(*args, **kwargs)\n",
            "  File \"/usr/local/lib/python3.10/dist-packages/telegram/bot.py\", line 2861, in get_updates\n",
            "    self._post(\n",
            "  File \"/usr/local/lib/python3.10/dist-packages/telegram/bot.py\", line 295, in _post\n",
            "    return self.request.post(\n",
            "  File \"/usr/local/lib/python3.10/dist-packages/telegram/utils/request.py\", line 356, in post\n",
            "    result = self._request_wrapper(\n",
            "  File \"/usr/local/lib/python3.10/dist-packages/telegram/utils/request.py\", line 283, in _request_wrapper\n",
            "    raise Conflict(message)\n",
            "telegram.error.Conflict: Conflict: terminated by other getUpdates request; make sure that only one bot instance is running\n",
            "ERROR:telegram.ext.updater:Error while getting Updates: Conflict: terminated by other getUpdates request; make sure that only one bot instance is running\n",
            "ERROR:telegram.ext.dispatcher:No error handlers are registered, logging exception.\n",
            "Traceback (most recent call last):\n",
            "  File \"/usr/local/lib/python3.10/dist-packages/telegram/ext/updater.py\", line 646, in _network_loop_retry\n",
            "    if not action_cb():\n",
            "  File \"/usr/local/lib/python3.10/dist-packages/telegram/ext/updater.py\", line 597, in polling_action_cb\n",
            "    updates = self.bot.get_updates(\n",
            "  File \"/usr/local/lib/python3.10/dist-packages/telegram/ext/extbot.py\", line 222, in get_updates\n",
            "    updates = super().get_updates(\n",
            "  File \"/usr/local/lib/python3.10/dist-packages/telegram/bot.py\", line 130, in decorator\n",
            "    result = func(*args, **kwargs)\n",
            "  File \"/usr/local/lib/python3.10/dist-packages/telegram/bot.py\", line 2861, in get_updates\n",
            "    self._post(\n",
            "  File \"/usr/local/lib/python3.10/dist-packages/telegram/bot.py\", line 295, in _post\n",
            "    return self.request.post(\n",
            "  File \"/usr/local/lib/python3.10/dist-packages/telegram/utils/request.py\", line 356, in post\n",
            "    result = self._request_wrapper(\n",
            "  File \"/usr/local/lib/python3.10/dist-packages/telegram/utils/request.py\", line 283, in _request_wrapper\n",
            "    raise Conflict(message)\n",
            "telegram.error.Conflict: Conflict: terminated by other getUpdates request; make sure that only one bot instance is running\n",
            "ERROR:telegram.ext.updater:Error while getting Updates: Conflict: terminated by other getUpdates request; make sure that only one bot instance is running\n",
            "ERROR:telegram.ext.dispatcher:No error handlers are registered, logging exception.\n",
            "Traceback (most recent call last):\n",
            "  File \"/usr/local/lib/python3.10/dist-packages/telegram/ext/updater.py\", line 646, in _network_loop_retry\n",
            "    if not action_cb():\n",
            "  File \"/usr/local/lib/python3.10/dist-packages/telegram/ext/updater.py\", line 597, in polling_action_cb\n",
            "    updates = self.bot.get_updates(\n",
            "  File \"/usr/local/lib/python3.10/dist-packages/telegram/ext/extbot.py\", line 222, in get_updates\n",
            "    updates = super().get_updates(\n",
            "  File \"/usr/local/lib/python3.10/dist-packages/telegram/bot.py\", line 130, in decorator\n",
            "    result = func(*args, **kwargs)\n",
            "  File \"/usr/local/lib/python3.10/dist-packages/telegram/bot.py\", line 2861, in get_updates\n",
            "    self._post(\n",
            "  File \"/usr/local/lib/python3.10/dist-packages/telegram/bot.py\", line 295, in _post\n",
            "    return self.request.post(\n",
            "  File \"/usr/local/lib/python3.10/dist-packages/telegram/utils/request.py\", line 356, in post\n",
            "    result = self._request_wrapper(\n",
            "  File \"/usr/local/lib/python3.10/dist-packages/telegram/utils/request.py\", line 283, in _request_wrapper\n",
            "    raise Conflict(message)\n",
            "telegram.error.Conflict: Conflict: terminated by other getUpdates request; make sure that only one bot instance is running\n",
            "ERROR:telegram.ext.updater:Error while getting Updates: Conflict: terminated by other getUpdates request; make sure that only one bot instance is running\n",
            "ERROR:telegram.ext.dispatcher:No error handlers are registered, logging exception.\n",
            "Traceback (most recent call last):\n",
            "  File \"/usr/local/lib/python3.10/dist-packages/telegram/ext/updater.py\", line 646, in _network_loop_retry\n",
            "    if not action_cb():\n",
            "  File \"/usr/local/lib/python3.10/dist-packages/telegram/ext/updater.py\", line 597, in polling_action_cb\n",
            "    updates = self.bot.get_updates(\n",
            "  File \"/usr/local/lib/python3.10/dist-packages/telegram/ext/extbot.py\", line 222, in get_updates\n",
            "    updates = super().get_updates(\n",
            "  File \"/usr/local/lib/python3.10/dist-packages/telegram/bot.py\", line 130, in decorator\n",
            "    result = func(*args, **kwargs)\n",
            "  File \"/usr/local/lib/python3.10/dist-packages/telegram/bot.py\", line 2861, in get_updates\n",
            "    self._post(\n",
            "  File \"/usr/local/lib/python3.10/dist-packages/telegram/bot.py\", line 295, in _post\n",
            "    return self.request.post(\n",
            "  File \"/usr/local/lib/python3.10/dist-packages/telegram/utils/request.py\", line 356, in post\n",
            "    result = self._request_wrapper(\n",
            "  File \"/usr/local/lib/python3.10/dist-packages/telegram/utils/request.py\", line 283, in _request_wrapper\n",
            "    raise Conflict(message)\n",
            "telegram.error.Conflict: Conflict: terminated by other getUpdates request; make sure that only one bot instance is running\n",
            "ERROR:telegram.ext.updater:Error while getting Updates: Conflict: terminated by other getUpdates request; make sure that only one bot instance is running\n",
            "ERROR:telegram.ext.dispatcher:No error handlers are registered, logging exception.\n",
            "Traceback (most recent call last):\n",
            "  File \"/usr/local/lib/python3.10/dist-packages/telegram/ext/updater.py\", line 646, in _network_loop_retry\n",
            "    if not action_cb():\n",
            "  File \"/usr/local/lib/python3.10/dist-packages/telegram/ext/updater.py\", line 597, in polling_action_cb\n",
            "    updates = self.bot.get_updates(\n",
            "  File \"/usr/local/lib/python3.10/dist-packages/telegram/ext/extbot.py\", line 222, in get_updates\n",
            "    updates = super().get_updates(\n",
            "  File \"/usr/local/lib/python3.10/dist-packages/telegram/bot.py\", line 130, in decorator\n",
            "    result = func(*args, **kwargs)\n",
            "  File \"/usr/local/lib/python3.10/dist-packages/telegram/bot.py\", line 2861, in get_updates\n",
            "    self._post(\n",
            "  File \"/usr/local/lib/python3.10/dist-packages/telegram/bot.py\", line 295, in _post\n",
            "    return self.request.post(\n",
            "  File \"/usr/local/lib/python3.10/dist-packages/telegram/utils/request.py\", line 356, in post\n",
            "    result = self._request_wrapper(\n",
            "  File \"/usr/local/lib/python3.10/dist-packages/telegram/utils/request.py\", line 283, in _request_wrapper\n",
            "    raise Conflict(message)\n",
            "telegram.error.Conflict: Conflict: terminated by other getUpdates request; make sure that only one bot instance is running\n",
            "ERROR:telegram.ext.updater:Error while getting Updates: Conflict: terminated by other getUpdates request; make sure that only one bot instance is running\n",
            "ERROR:telegram.ext.dispatcher:No error handlers are registered, logging exception.\n",
            "Traceback (most recent call last):\n",
            "  File \"/usr/local/lib/python3.10/dist-packages/telegram/ext/updater.py\", line 646, in _network_loop_retry\n",
            "    if not action_cb():\n",
            "  File \"/usr/local/lib/python3.10/dist-packages/telegram/ext/updater.py\", line 597, in polling_action_cb\n",
            "    updates = self.bot.get_updates(\n",
            "  File \"/usr/local/lib/python3.10/dist-packages/telegram/ext/extbot.py\", line 222, in get_updates\n",
            "    updates = super().get_updates(\n",
            "  File \"/usr/local/lib/python3.10/dist-packages/telegram/bot.py\", line 130, in decorator\n",
            "    result = func(*args, **kwargs)\n",
            "  File \"/usr/local/lib/python3.10/dist-packages/telegram/bot.py\", line 2861, in get_updates\n",
            "    self._post(\n",
            "  File \"/usr/local/lib/python3.10/dist-packages/telegram/bot.py\", line 295, in _post\n",
            "    return self.request.post(\n",
            "  File \"/usr/local/lib/python3.10/dist-packages/telegram/utils/request.py\", line 356, in post\n",
            "    result = self._request_wrapper(\n",
            "  File \"/usr/local/lib/python3.10/dist-packages/telegram/utils/request.py\", line 283, in _request_wrapper\n",
            "    raise Conflict(message)\n",
            "telegram.error.Conflict: Conflict: terminated by other getUpdates request; make sure that only one bot instance is running\n",
            "ERROR:telegram.ext.updater:Error while getting Updates: Conflict: terminated by other getUpdates request; make sure that only one bot instance is running\n",
            "ERROR:telegram.ext.dispatcher:No error handlers are registered, logging exception.\n",
            "Traceback (most recent call last):\n",
            "  File \"/usr/local/lib/python3.10/dist-packages/telegram/ext/updater.py\", line 646, in _network_loop_retry\n",
            "    if not action_cb():\n",
            "  File \"/usr/local/lib/python3.10/dist-packages/telegram/ext/updater.py\", line 597, in polling_action_cb\n",
            "    updates = self.bot.get_updates(\n",
            "  File \"/usr/local/lib/python3.10/dist-packages/telegram/ext/extbot.py\", line 222, in get_updates\n",
            "    updates = super().get_updates(\n",
            "  File \"/usr/local/lib/python3.10/dist-packages/telegram/bot.py\", line 130, in decorator\n",
            "    result = func(*args, **kwargs)\n",
            "  File \"/usr/local/lib/python3.10/dist-packages/telegram/bot.py\", line 2861, in get_updates\n",
            "    self._post(\n",
            "  File \"/usr/local/lib/python3.10/dist-packages/telegram/bot.py\", line 295, in _post\n",
            "    return self.request.post(\n",
            "  File \"/usr/local/lib/python3.10/dist-packages/telegram/utils/request.py\", line 356, in post\n",
            "    result = self._request_wrapper(\n",
            "  File \"/usr/local/lib/python3.10/dist-packages/telegram/utils/request.py\", line 283, in _request_wrapper\n",
            "    raise Conflict(message)\n",
            "telegram.error.Conflict: Conflict: terminated by other getUpdates request; make sure that only one bot instance is running\n",
            "ERROR:telegram.ext.updater:Error while getting Updates: Conflict: terminated by other getUpdates request; make sure that only one bot instance is running\n",
            "ERROR:telegram.ext.dispatcher:No error handlers are registered, logging exception.\n",
            "Traceback (most recent call last):\n",
            "  File \"/usr/local/lib/python3.10/dist-packages/telegram/ext/updater.py\", line 646, in _network_loop_retry\n",
            "    if not action_cb():\n",
            "  File \"/usr/local/lib/python3.10/dist-packages/telegram/ext/updater.py\", line 597, in polling_action_cb\n",
            "    updates = self.bot.get_updates(\n",
            "  File \"/usr/local/lib/python3.10/dist-packages/telegram/ext/extbot.py\", line 222, in get_updates\n",
            "    updates = super().get_updates(\n",
            "  File \"/usr/local/lib/python3.10/dist-packages/telegram/bot.py\", line 130, in decorator\n",
            "    result = func(*args, **kwargs)\n",
            "  File \"/usr/local/lib/python3.10/dist-packages/telegram/bot.py\", line 2861, in get_updates\n",
            "    self._post(\n",
            "  File \"/usr/local/lib/python3.10/dist-packages/telegram/bot.py\", line 295, in _post\n",
            "    return self.request.post(\n",
            "  File \"/usr/local/lib/python3.10/dist-packages/telegram/utils/request.py\", line 356, in post\n",
            "    result = self._request_wrapper(\n",
            "  File \"/usr/local/lib/python3.10/dist-packages/telegram/utils/request.py\", line 283, in _request_wrapper\n",
            "    raise Conflict(message)\n",
            "telegram.error.Conflict: Conflict: terminated by other getUpdates request; make sure that only one bot instance is running\n",
            "ERROR:telegram.ext.updater:Error while getting Updates: Conflict: terminated by other getUpdates request; make sure that only one bot instance is running\n",
            "ERROR:telegram.ext.dispatcher:No error handlers are registered, logging exception.\n",
            "Traceback (most recent call last):\n",
            "  File \"/usr/local/lib/python3.10/dist-packages/telegram/ext/updater.py\", line 646, in _network_loop_retry\n",
            "    if not action_cb():\n",
            "  File \"/usr/local/lib/python3.10/dist-packages/telegram/ext/updater.py\", line 597, in polling_action_cb\n",
            "    updates = self.bot.get_updates(\n",
            "  File \"/usr/local/lib/python3.10/dist-packages/telegram/ext/extbot.py\", line 222, in get_updates\n",
            "    updates = super().get_updates(\n",
            "  File \"/usr/local/lib/python3.10/dist-packages/telegram/bot.py\", line 130, in decorator\n",
            "    result = func(*args, **kwargs)\n",
            "  File \"/usr/local/lib/python3.10/dist-packages/telegram/bot.py\", line 2861, in get_updates\n",
            "    self._post(\n",
            "  File \"/usr/local/lib/python3.10/dist-packages/telegram/bot.py\", line 295, in _post\n",
            "    return self.request.post(\n",
            "  File \"/usr/local/lib/python3.10/dist-packages/telegram/utils/request.py\", line 356, in post\n",
            "    result = self._request_wrapper(\n",
            "  File \"/usr/local/lib/python3.10/dist-packages/telegram/utils/request.py\", line 283, in _request_wrapper\n",
            "    raise Conflict(message)\n",
            "telegram.error.Conflict: Conflict: terminated by other getUpdates request; make sure that only one bot instance is running\n",
            "ERROR:telegram.ext.updater:Error while getting Updates: Conflict: terminated by other getUpdates request; make sure that only one bot instance is running\n",
            "ERROR:telegram.ext.dispatcher:No error handlers are registered, logging exception.\n",
            "Traceback (most recent call last):\n",
            "  File \"/usr/local/lib/python3.10/dist-packages/telegram/ext/updater.py\", line 646, in _network_loop_retry\n",
            "    if not action_cb():\n",
            "  File \"/usr/local/lib/python3.10/dist-packages/telegram/ext/updater.py\", line 597, in polling_action_cb\n",
            "    updates = self.bot.get_updates(\n",
            "  File \"/usr/local/lib/python3.10/dist-packages/telegram/ext/extbot.py\", line 222, in get_updates\n",
            "    updates = super().get_updates(\n",
            "  File \"/usr/local/lib/python3.10/dist-packages/telegram/bot.py\", line 130, in decorator\n",
            "    result = func(*args, **kwargs)\n",
            "  File \"/usr/local/lib/python3.10/dist-packages/telegram/bot.py\", line 2861, in get_updates\n",
            "    self._post(\n",
            "  File \"/usr/local/lib/python3.10/dist-packages/telegram/bot.py\", line 295, in _post\n",
            "    return self.request.post(\n",
            "  File \"/usr/local/lib/python3.10/dist-packages/telegram/utils/request.py\", line 356, in post\n",
            "    result = self._request_wrapper(\n",
            "  File \"/usr/local/lib/python3.10/dist-packages/telegram/utils/request.py\", line 283, in _request_wrapper\n",
            "    raise Conflict(message)\n",
            "telegram.error.Conflict: Conflict: terminated by other getUpdates request; make sure that only one bot instance is running\n",
            "ERROR:telegram.ext.updater:Error while getting Updates: Conflict: terminated by other getUpdates request; make sure that only one bot instance is running\n",
            "ERROR:telegram.ext.dispatcher:No error handlers are registered, logging exception.\n",
            "Traceback (most recent call last):\n",
            "  File \"/usr/local/lib/python3.10/dist-packages/telegram/ext/updater.py\", line 646, in _network_loop_retry\n",
            "    if not action_cb():\n",
            "  File \"/usr/local/lib/python3.10/dist-packages/telegram/ext/updater.py\", line 597, in polling_action_cb\n",
            "    updates = self.bot.get_updates(\n",
            "  File \"/usr/local/lib/python3.10/dist-packages/telegram/ext/extbot.py\", line 222, in get_updates\n",
            "    updates = super().get_updates(\n",
            "  File \"/usr/local/lib/python3.10/dist-packages/telegram/bot.py\", line 130, in decorator\n",
            "    result = func(*args, **kwargs)\n",
            "  File \"/usr/local/lib/python3.10/dist-packages/telegram/bot.py\", line 2861, in get_updates\n",
            "    self._post(\n",
            "  File \"/usr/local/lib/python3.10/dist-packages/telegram/bot.py\", line 295, in _post\n",
            "    return self.request.post(\n",
            "  File \"/usr/local/lib/python3.10/dist-packages/telegram/utils/request.py\", line 356, in post\n",
            "    result = self._request_wrapper(\n",
            "  File \"/usr/local/lib/python3.10/dist-packages/telegram/utils/request.py\", line 283, in _request_wrapper\n",
            "    raise Conflict(message)\n",
            "telegram.error.Conflict: Conflict: terminated by other getUpdates request; make sure that only one bot instance is running\n",
            "ERROR:telegram.ext.updater:Error while getting Updates: Conflict: terminated by other getUpdates request; make sure that only one bot instance is running\n",
            "ERROR:telegram.ext.dispatcher:No error handlers are registered, logging exception.\n",
            "Traceback (most recent call last):\n",
            "  File \"/usr/local/lib/python3.10/dist-packages/telegram/ext/updater.py\", line 646, in _network_loop_retry\n",
            "    if not action_cb():\n",
            "  File \"/usr/local/lib/python3.10/dist-packages/telegram/ext/updater.py\", line 597, in polling_action_cb\n",
            "    updates = self.bot.get_updates(\n",
            "  File \"/usr/local/lib/python3.10/dist-packages/telegram/ext/extbot.py\", line 222, in get_updates\n",
            "    updates = super().get_updates(\n",
            "  File \"/usr/local/lib/python3.10/dist-packages/telegram/bot.py\", line 130, in decorator\n",
            "    result = func(*args, **kwargs)\n",
            "  File \"/usr/local/lib/python3.10/dist-packages/telegram/bot.py\", line 2861, in get_updates\n",
            "    self._post(\n",
            "  File \"/usr/local/lib/python3.10/dist-packages/telegram/bot.py\", line 295, in _post\n",
            "    return self.request.post(\n",
            "  File \"/usr/local/lib/python3.10/dist-packages/telegram/utils/request.py\", line 356, in post\n",
            "    result = self._request_wrapper(\n",
            "  File \"/usr/local/lib/python3.10/dist-packages/telegram/utils/request.py\", line 283, in _request_wrapper\n",
            "    raise Conflict(message)\n",
            "telegram.error.Conflict: Conflict: terminated by other getUpdates request; make sure that only one bot instance is running\n",
            "ERROR:telegram.ext.updater:Error while getting Updates: Conflict: terminated by other getUpdates request; make sure that only one bot instance is running\n",
            "ERROR:telegram.ext.dispatcher:No error handlers are registered, logging exception.\n",
            "Traceback (most recent call last):\n",
            "  File \"/usr/local/lib/python3.10/dist-packages/telegram/ext/updater.py\", line 646, in _network_loop_retry\n",
            "    if not action_cb():\n",
            "  File \"/usr/local/lib/python3.10/dist-packages/telegram/ext/updater.py\", line 597, in polling_action_cb\n",
            "    updates = self.bot.get_updates(\n",
            "  File \"/usr/local/lib/python3.10/dist-packages/telegram/ext/extbot.py\", line 222, in get_updates\n",
            "    updates = super().get_updates(\n",
            "  File \"/usr/local/lib/python3.10/dist-packages/telegram/bot.py\", line 130, in decorator\n",
            "    result = func(*args, **kwargs)\n",
            "  File \"/usr/local/lib/python3.10/dist-packages/telegram/bot.py\", line 2861, in get_updates\n",
            "    self._post(\n",
            "  File \"/usr/local/lib/python3.10/dist-packages/telegram/bot.py\", line 295, in _post\n",
            "    return self.request.post(\n",
            "  File \"/usr/local/lib/python3.10/dist-packages/telegram/utils/request.py\", line 356, in post\n",
            "    result = self._request_wrapper(\n",
            "  File \"/usr/local/lib/python3.10/dist-packages/telegram/utils/request.py\", line 283, in _request_wrapper\n",
            "    raise Conflict(message)\n",
            "telegram.error.Conflict: Conflict: terminated by other getUpdates request; make sure that only one bot instance is running\n",
            "ERROR:telegram.ext.updater:Error while getting Updates: Conflict: terminated by other getUpdates request; make sure that only one bot instance is running\n",
            "ERROR:telegram.ext.dispatcher:No error handlers are registered, logging exception.\n",
            "Traceback (most recent call last):\n",
            "  File \"/usr/local/lib/python3.10/dist-packages/telegram/ext/updater.py\", line 646, in _network_loop_retry\n",
            "    if not action_cb():\n",
            "  File \"/usr/local/lib/python3.10/dist-packages/telegram/ext/updater.py\", line 597, in polling_action_cb\n",
            "    updates = self.bot.get_updates(\n",
            "  File \"/usr/local/lib/python3.10/dist-packages/telegram/ext/extbot.py\", line 222, in get_updates\n",
            "    updates = super().get_updates(\n",
            "  File \"/usr/local/lib/python3.10/dist-packages/telegram/bot.py\", line 130, in decorator\n",
            "    result = func(*args, **kwargs)\n",
            "  File \"/usr/local/lib/python3.10/dist-packages/telegram/bot.py\", line 2861, in get_updates\n",
            "    self._post(\n",
            "  File \"/usr/local/lib/python3.10/dist-packages/telegram/bot.py\", line 295, in _post\n",
            "    return self.request.post(\n",
            "  File \"/usr/local/lib/python3.10/dist-packages/telegram/utils/request.py\", line 356, in post\n",
            "    result = self._request_wrapper(\n",
            "  File \"/usr/local/lib/python3.10/dist-packages/telegram/utils/request.py\", line 283, in _request_wrapper\n",
            "    raise Conflict(message)\n",
            "telegram.error.Conflict: Conflict: terminated by other getUpdates request; make sure that only one bot instance is running\n",
            "ERROR:telegram.ext.updater:Error while getting Updates: Conflict: terminated by other getUpdates request; make sure that only one bot instance is running\n",
            "ERROR:telegram.ext.dispatcher:No error handlers are registered, logging exception.\n",
            "Traceback (most recent call last):\n",
            "  File \"/usr/local/lib/python3.10/dist-packages/telegram/ext/updater.py\", line 646, in _network_loop_retry\n",
            "    if not action_cb():\n",
            "  File \"/usr/local/lib/python3.10/dist-packages/telegram/ext/updater.py\", line 597, in polling_action_cb\n",
            "    updates = self.bot.get_updates(\n",
            "  File \"/usr/local/lib/python3.10/dist-packages/telegram/ext/extbot.py\", line 222, in get_updates\n",
            "    updates = super().get_updates(\n",
            "  File \"/usr/local/lib/python3.10/dist-packages/telegram/bot.py\", line 130, in decorator\n",
            "    result = func(*args, **kwargs)\n",
            "  File \"/usr/local/lib/python3.10/dist-packages/telegram/bot.py\", line 2861, in get_updates\n",
            "    self._post(\n",
            "  File \"/usr/local/lib/python3.10/dist-packages/telegram/bot.py\", line 295, in _post\n",
            "    return self.request.post(\n",
            "  File \"/usr/local/lib/python3.10/dist-packages/telegram/utils/request.py\", line 356, in post\n",
            "    result = self._request_wrapper(\n",
            "  File \"/usr/local/lib/python3.10/dist-packages/telegram/utils/request.py\", line 283, in _request_wrapper\n",
            "    raise Conflict(message)\n",
            "telegram.error.Conflict: Conflict: terminated by other getUpdates request; make sure that only one bot instance is running\n",
            "ERROR:telegram.ext.updater:Error while getting Updates: Conflict: terminated by other getUpdates request; make sure that only one bot instance is running\n",
            "ERROR:telegram.ext.dispatcher:No error handlers are registered, logging exception.\n",
            "Traceback (most recent call last):\n",
            "  File \"/usr/local/lib/python3.10/dist-packages/telegram/ext/updater.py\", line 646, in _network_loop_retry\n",
            "    if not action_cb():\n",
            "  File \"/usr/local/lib/python3.10/dist-packages/telegram/ext/updater.py\", line 597, in polling_action_cb\n",
            "    updates = self.bot.get_updates(\n",
            "  File \"/usr/local/lib/python3.10/dist-packages/telegram/ext/extbot.py\", line 222, in get_updates\n",
            "    updates = super().get_updates(\n",
            "  File \"/usr/local/lib/python3.10/dist-packages/telegram/bot.py\", line 130, in decorator\n",
            "    result = func(*args, **kwargs)\n",
            "  File \"/usr/local/lib/python3.10/dist-packages/telegram/bot.py\", line 2861, in get_updates\n",
            "    self._post(\n",
            "  File \"/usr/local/lib/python3.10/dist-packages/telegram/bot.py\", line 295, in _post\n",
            "    return self.request.post(\n",
            "  File \"/usr/local/lib/python3.10/dist-packages/telegram/utils/request.py\", line 356, in post\n",
            "    result = self._request_wrapper(\n",
            "  File \"/usr/local/lib/python3.10/dist-packages/telegram/utils/request.py\", line 283, in _request_wrapper\n",
            "    raise Conflict(message)\n",
            "telegram.error.Conflict: Conflict: terminated by other getUpdates request; make sure that only one bot instance is running\n",
            "ERROR:telegram.ext.updater:Error while getting Updates: Conflict: terminated by other getUpdates request; make sure that only one bot instance is running\n",
            "ERROR:telegram.ext.dispatcher:No error handlers are registered, logging exception.\n",
            "Traceback (most recent call last):\n",
            "  File \"/usr/local/lib/python3.10/dist-packages/telegram/ext/updater.py\", line 646, in _network_loop_retry\n",
            "    if not action_cb():\n",
            "  File \"/usr/local/lib/python3.10/dist-packages/telegram/ext/updater.py\", line 597, in polling_action_cb\n",
            "    updates = self.bot.get_updates(\n",
            "  File \"/usr/local/lib/python3.10/dist-packages/telegram/ext/extbot.py\", line 222, in get_updates\n",
            "    updates = super().get_updates(\n",
            "  File \"/usr/local/lib/python3.10/dist-packages/telegram/bot.py\", line 130, in decorator\n",
            "    result = func(*args, **kwargs)\n",
            "  File \"/usr/local/lib/python3.10/dist-packages/telegram/bot.py\", line 2861, in get_updates\n",
            "    self._post(\n",
            "  File \"/usr/local/lib/python3.10/dist-packages/telegram/bot.py\", line 295, in _post\n",
            "    return self.request.post(\n",
            "  File \"/usr/local/lib/python3.10/dist-packages/telegram/utils/request.py\", line 356, in post\n",
            "    result = self._request_wrapper(\n",
            "  File \"/usr/local/lib/python3.10/dist-packages/telegram/utils/request.py\", line 283, in _request_wrapper\n",
            "    raise Conflict(message)\n",
            "telegram.error.Conflict: Conflict: terminated by other getUpdates request; make sure that only one bot instance is running\n",
            "ERROR:telegram.ext.updater:Error while getting Updates: Conflict: terminated by other getUpdates request; make sure that only one bot instance is running\n",
            "ERROR:telegram.ext.dispatcher:No error handlers are registered, logging exception.\n",
            "Traceback (most recent call last):\n",
            "  File \"/usr/local/lib/python3.10/dist-packages/telegram/ext/updater.py\", line 646, in _network_loop_retry\n",
            "    if not action_cb():\n",
            "  File \"/usr/local/lib/python3.10/dist-packages/telegram/ext/updater.py\", line 597, in polling_action_cb\n",
            "    updates = self.bot.get_updates(\n",
            "  File \"/usr/local/lib/python3.10/dist-packages/telegram/ext/extbot.py\", line 222, in get_updates\n",
            "    updates = super().get_updates(\n",
            "  File \"/usr/local/lib/python3.10/dist-packages/telegram/bot.py\", line 130, in decorator\n",
            "    result = func(*args, **kwargs)\n",
            "  File \"/usr/local/lib/python3.10/dist-packages/telegram/bot.py\", line 2861, in get_updates\n",
            "    self._post(\n",
            "  File \"/usr/local/lib/python3.10/dist-packages/telegram/bot.py\", line 295, in _post\n",
            "    return self.request.post(\n",
            "  File \"/usr/local/lib/python3.10/dist-packages/telegram/utils/request.py\", line 356, in post\n",
            "    result = self._request_wrapper(\n",
            "  File \"/usr/local/lib/python3.10/dist-packages/telegram/utils/request.py\", line 283, in _request_wrapper\n",
            "    raise Conflict(message)\n",
            "telegram.error.Conflict: Conflict: terminated by other getUpdates request; make sure that only one bot instance is running\n",
            "ERROR:telegram.ext.updater:Error while getting Updates: Conflict: terminated by other getUpdates request; make sure that only one bot instance is running\n",
            "ERROR:telegram.ext.dispatcher:No error handlers are registered, logging exception.\n",
            "Traceback (most recent call last):\n",
            "  File \"/usr/local/lib/python3.10/dist-packages/telegram/ext/updater.py\", line 646, in _network_loop_retry\n",
            "    if not action_cb():\n",
            "  File \"/usr/local/lib/python3.10/dist-packages/telegram/ext/updater.py\", line 597, in polling_action_cb\n",
            "    updates = self.bot.get_updates(\n",
            "  File \"/usr/local/lib/python3.10/dist-packages/telegram/ext/extbot.py\", line 222, in get_updates\n",
            "    updates = super().get_updates(\n",
            "  File \"/usr/local/lib/python3.10/dist-packages/telegram/bot.py\", line 130, in decorator\n",
            "    result = func(*args, **kwargs)\n",
            "  File \"/usr/local/lib/python3.10/dist-packages/telegram/bot.py\", line 2861, in get_updates\n",
            "    self._post(\n",
            "  File \"/usr/local/lib/python3.10/dist-packages/telegram/bot.py\", line 295, in _post\n",
            "    return self.request.post(\n",
            "  File \"/usr/local/lib/python3.10/dist-packages/telegram/utils/request.py\", line 356, in post\n",
            "    result = self._request_wrapper(\n",
            "  File \"/usr/local/lib/python3.10/dist-packages/telegram/utils/request.py\", line 283, in _request_wrapper\n",
            "    raise Conflict(message)\n",
            "telegram.error.Conflict: Conflict: terminated by other getUpdates request; make sure that only one bot instance is running\n",
            "ERROR:telegram.ext.updater:Error while getting Updates: Conflict: terminated by other getUpdates request; make sure that only one bot instance is running\n",
            "ERROR:telegram.ext.dispatcher:No error handlers are registered, logging exception.\n",
            "Traceback (most recent call last):\n",
            "  File \"/usr/local/lib/python3.10/dist-packages/telegram/ext/updater.py\", line 646, in _network_loop_retry\n",
            "    if not action_cb():\n",
            "  File \"/usr/local/lib/python3.10/dist-packages/telegram/ext/updater.py\", line 597, in polling_action_cb\n",
            "    updates = self.bot.get_updates(\n",
            "  File \"/usr/local/lib/python3.10/dist-packages/telegram/ext/extbot.py\", line 222, in get_updates\n",
            "    updates = super().get_updates(\n",
            "  File \"/usr/local/lib/python3.10/dist-packages/telegram/bot.py\", line 130, in decorator\n",
            "    result = func(*args, **kwargs)\n",
            "  File \"/usr/local/lib/python3.10/dist-packages/telegram/bot.py\", line 2861, in get_updates\n",
            "    self._post(\n",
            "  File \"/usr/local/lib/python3.10/dist-packages/telegram/bot.py\", line 295, in _post\n",
            "    return self.request.post(\n",
            "  File \"/usr/local/lib/python3.10/dist-packages/telegram/utils/request.py\", line 356, in post\n",
            "    result = self._request_wrapper(\n",
            "  File \"/usr/local/lib/python3.10/dist-packages/telegram/utils/request.py\", line 283, in _request_wrapper\n",
            "    raise Conflict(message)\n",
            "telegram.error.Conflict: Conflict: terminated by other getUpdates request; make sure that only one bot instance is running\n",
            "ERROR:telegram.ext.updater:Error while getting Updates: Conflict: terminated by other getUpdates request; make sure that only one bot instance is running\n",
            "ERROR:telegram.ext.dispatcher:No error handlers are registered, logging exception.\n",
            "Traceback (most recent call last):\n",
            "  File \"/usr/local/lib/python3.10/dist-packages/telegram/ext/updater.py\", line 646, in _network_loop_retry\n",
            "    if not action_cb():\n",
            "  File \"/usr/local/lib/python3.10/dist-packages/telegram/ext/updater.py\", line 597, in polling_action_cb\n",
            "    updates = self.bot.get_updates(\n",
            "  File \"/usr/local/lib/python3.10/dist-packages/telegram/ext/extbot.py\", line 222, in get_updates\n",
            "    updates = super().get_updates(\n",
            "  File \"/usr/local/lib/python3.10/dist-packages/telegram/bot.py\", line 130, in decorator\n",
            "    result = func(*args, **kwargs)\n",
            "  File \"/usr/local/lib/python3.10/dist-packages/telegram/bot.py\", line 2861, in get_updates\n",
            "    self._post(\n",
            "  File \"/usr/local/lib/python3.10/dist-packages/telegram/bot.py\", line 295, in _post\n",
            "    return self.request.post(\n",
            "  File \"/usr/local/lib/python3.10/dist-packages/telegram/utils/request.py\", line 356, in post\n",
            "    result = self._request_wrapper(\n",
            "  File \"/usr/local/lib/python3.10/dist-packages/telegram/utils/request.py\", line 283, in _request_wrapper\n",
            "    raise Conflict(message)\n",
            "telegram.error.Conflict: Conflict: terminated by other getUpdates request; make sure that only one bot instance is running\n",
            "ERROR:telegram.ext.updater:Error while getting Updates: Conflict: terminated by other getUpdates request; make sure that only one bot instance is running\n",
            "ERROR:telegram.ext.dispatcher:No error handlers are registered, logging exception.\n",
            "Traceback (most recent call last):\n",
            "  File \"/usr/local/lib/python3.10/dist-packages/telegram/ext/updater.py\", line 646, in _network_loop_retry\n",
            "    if not action_cb():\n",
            "  File \"/usr/local/lib/python3.10/dist-packages/telegram/ext/updater.py\", line 597, in polling_action_cb\n",
            "    updates = self.bot.get_updates(\n",
            "  File \"/usr/local/lib/python3.10/dist-packages/telegram/ext/extbot.py\", line 222, in get_updates\n",
            "    updates = super().get_updates(\n",
            "  File \"/usr/local/lib/python3.10/dist-packages/telegram/bot.py\", line 130, in decorator\n",
            "    result = func(*args, **kwargs)\n",
            "  File \"/usr/local/lib/python3.10/dist-packages/telegram/bot.py\", line 2861, in get_updates\n",
            "    self._post(\n",
            "  File \"/usr/local/lib/python3.10/dist-packages/telegram/bot.py\", line 295, in _post\n",
            "    return self.request.post(\n",
            "  File \"/usr/local/lib/python3.10/dist-packages/telegram/utils/request.py\", line 356, in post\n",
            "    result = self._request_wrapper(\n",
            "  File \"/usr/local/lib/python3.10/dist-packages/telegram/utils/request.py\", line 283, in _request_wrapper\n",
            "    raise Conflict(message)\n",
            "telegram.error.Conflict: Conflict: terminated by other getUpdates request; make sure that only one bot instance is running\n",
            "ERROR:telegram.ext.updater:Error while getting Updates: Conflict: terminated by other getUpdates request; make sure that only one bot instance is running\n",
            "ERROR:telegram.ext.dispatcher:No error handlers are registered, logging exception.\n",
            "Traceback (most recent call last):\n",
            "  File \"/usr/local/lib/python3.10/dist-packages/telegram/ext/updater.py\", line 646, in _network_loop_retry\n",
            "    if not action_cb():\n",
            "  File \"/usr/local/lib/python3.10/dist-packages/telegram/ext/updater.py\", line 597, in polling_action_cb\n",
            "    updates = self.bot.get_updates(\n",
            "  File \"/usr/local/lib/python3.10/dist-packages/telegram/ext/extbot.py\", line 222, in get_updates\n",
            "    updates = super().get_updates(\n",
            "  File \"/usr/local/lib/python3.10/dist-packages/telegram/bot.py\", line 130, in decorator\n",
            "    result = func(*args, **kwargs)\n",
            "  File \"/usr/local/lib/python3.10/dist-packages/telegram/bot.py\", line 2861, in get_updates\n",
            "    self._post(\n",
            "  File \"/usr/local/lib/python3.10/dist-packages/telegram/bot.py\", line 295, in _post\n",
            "    return self.request.post(\n",
            "  File \"/usr/local/lib/python3.10/dist-packages/telegram/utils/request.py\", line 356, in post\n",
            "    result = self._request_wrapper(\n",
            "  File \"/usr/local/lib/python3.10/dist-packages/telegram/utils/request.py\", line 283, in _request_wrapper\n",
            "    raise Conflict(message)\n",
            "telegram.error.Conflict: Conflict: terminated by other getUpdates request; make sure that only one bot instance is running\n",
            "ERROR:telegram.ext.updater:Error while getting Updates: Conflict: terminated by other getUpdates request; make sure that only one bot instance is running\n",
            "ERROR:telegram.ext.dispatcher:No error handlers are registered, logging exception.\n",
            "Traceback (most recent call last):\n",
            "  File \"/usr/local/lib/python3.10/dist-packages/telegram/ext/updater.py\", line 646, in _network_loop_retry\n",
            "    if not action_cb():\n",
            "  File \"/usr/local/lib/python3.10/dist-packages/telegram/ext/updater.py\", line 597, in polling_action_cb\n",
            "    updates = self.bot.get_updates(\n",
            "  File \"/usr/local/lib/python3.10/dist-packages/telegram/ext/extbot.py\", line 222, in get_updates\n",
            "    updates = super().get_updates(\n",
            "  File \"/usr/local/lib/python3.10/dist-packages/telegram/bot.py\", line 130, in decorator\n",
            "    result = func(*args, **kwargs)\n",
            "  File \"/usr/local/lib/python3.10/dist-packages/telegram/bot.py\", line 2861, in get_updates\n",
            "    self._post(\n",
            "  File \"/usr/local/lib/python3.10/dist-packages/telegram/bot.py\", line 295, in _post\n",
            "    return self.request.post(\n",
            "  File \"/usr/local/lib/python3.10/dist-packages/telegram/utils/request.py\", line 356, in post\n",
            "    result = self._request_wrapper(\n",
            "  File \"/usr/local/lib/python3.10/dist-packages/telegram/utils/request.py\", line 283, in _request_wrapper\n",
            "    raise Conflict(message)\n",
            "telegram.error.Conflict: Conflict: terminated by other getUpdates request; make sure that only one bot instance is running\n",
            "ERROR:telegram.ext.updater:Error while getting Updates: Conflict: terminated by other getUpdates request; make sure that only one bot instance is running\n",
            "ERROR:telegram.ext.dispatcher:No error handlers are registered, logging exception.\n",
            "Traceback (most recent call last):\n",
            "  File \"/usr/local/lib/python3.10/dist-packages/telegram/ext/updater.py\", line 646, in _network_loop_retry\n",
            "    if not action_cb():\n",
            "  File \"/usr/local/lib/python3.10/dist-packages/telegram/ext/updater.py\", line 597, in polling_action_cb\n",
            "    updates = self.bot.get_updates(\n",
            "  File \"/usr/local/lib/python3.10/dist-packages/telegram/ext/extbot.py\", line 222, in get_updates\n",
            "    updates = super().get_updates(\n",
            "  File \"/usr/local/lib/python3.10/dist-packages/telegram/bot.py\", line 130, in decorator\n",
            "    result = func(*args, **kwargs)\n",
            "  File \"/usr/local/lib/python3.10/dist-packages/telegram/bot.py\", line 2861, in get_updates\n",
            "    self._post(\n",
            "  File \"/usr/local/lib/python3.10/dist-packages/telegram/bot.py\", line 295, in _post\n",
            "    return self.request.post(\n",
            "  File \"/usr/local/lib/python3.10/dist-packages/telegram/utils/request.py\", line 356, in post\n",
            "    result = self._request_wrapper(\n",
            "  File \"/usr/local/lib/python3.10/dist-packages/telegram/utils/request.py\", line 283, in _request_wrapper\n",
            "    raise Conflict(message)\n",
            "telegram.error.Conflict: Conflict: terminated by other getUpdates request; make sure that only one bot instance is running\n",
            "ERROR:telegram.ext.updater:Error while getting Updates: Conflict: terminated by other getUpdates request; make sure that only one bot instance is running\n",
            "ERROR:telegram.ext.dispatcher:No error handlers are registered, logging exception.\n",
            "Traceback (most recent call last):\n",
            "  File \"/usr/local/lib/python3.10/dist-packages/telegram/ext/updater.py\", line 646, in _network_loop_retry\n",
            "    if not action_cb():\n",
            "  File \"/usr/local/lib/python3.10/dist-packages/telegram/ext/updater.py\", line 597, in polling_action_cb\n",
            "    updates = self.bot.get_updates(\n",
            "  File \"/usr/local/lib/python3.10/dist-packages/telegram/ext/extbot.py\", line 222, in get_updates\n",
            "    updates = super().get_updates(\n",
            "  File \"/usr/local/lib/python3.10/dist-packages/telegram/bot.py\", line 130, in decorator\n",
            "    result = func(*args, **kwargs)\n",
            "  File \"/usr/local/lib/python3.10/dist-packages/telegram/bot.py\", line 2861, in get_updates\n",
            "    self._post(\n",
            "  File \"/usr/local/lib/python3.10/dist-packages/telegram/bot.py\", line 295, in _post\n",
            "    return self.request.post(\n",
            "  File \"/usr/local/lib/python3.10/dist-packages/telegram/utils/request.py\", line 356, in post\n",
            "    result = self._request_wrapper(\n",
            "  File \"/usr/local/lib/python3.10/dist-packages/telegram/utils/request.py\", line 283, in _request_wrapper\n",
            "    raise Conflict(message)\n",
            "telegram.error.Conflict: Conflict: terminated by other getUpdates request; make sure that only one bot instance is running\n",
            "ERROR:telegram.ext.updater:Error while getting Updates: Conflict: terminated by other getUpdates request; make sure that only one bot instance is running\n",
            "ERROR:telegram.ext.dispatcher:No error handlers are registered, logging exception.\n",
            "Traceback (most recent call last):\n",
            "  File \"/usr/local/lib/python3.10/dist-packages/telegram/ext/updater.py\", line 646, in _network_loop_retry\n",
            "    if not action_cb():\n",
            "  File \"/usr/local/lib/python3.10/dist-packages/telegram/ext/updater.py\", line 597, in polling_action_cb\n",
            "    updates = self.bot.get_updates(\n",
            "  File \"/usr/local/lib/python3.10/dist-packages/telegram/ext/extbot.py\", line 222, in get_updates\n",
            "    updates = super().get_updates(\n",
            "  File \"/usr/local/lib/python3.10/dist-packages/telegram/bot.py\", line 130, in decorator\n",
            "    result = func(*args, **kwargs)\n",
            "  File \"/usr/local/lib/python3.10/dist-packages/telegram/bot.py\", line 2861, in get_updates\n",
            "    self._post(\n",
            "  File \"/usr/local/lib/python3.10/dist-packages/telegram/bot.py\", line 295, in _post\n",
            "    return self.request.post(\n",
            "  File \"/usr/local/lib/python3.10/dist-packages/telegram/utils/request.py\", line 356, in post\n",
            "    result = self._request_wrapper(\n",
            "  File \"/usr/local/lib/python3.10/dist-packages/telegram/utils/request.py\", line 283, in _request_wrapper\n",
            "    raise Conflict(message)\n",
            "telegram.error.Conflict: Conflict: terminated by other getUpdates request; make sure that only one bot instance is running\n",
            "ERROR:telegram.ext.updater:Error while getting Updates: Conflict: terminated by other getUpdates request; make sure that only one bot instance is running\n",
            "ERROR:telegram.ext.dispatcher:No error handlers are registered, logging exception.\n",
            "Traceback (most recent call last):\n",
            "  File \"/usr/local/lib/python3.10/dist-packages/telegram/ext/updater.py\", line 646, in _network_loop_retry\n",
            "    if not action_cb():\n",
            "  File \"/usr/local/lib/python3.10/dist-packages/telegram/ext/updater.py\", line 597, in polling_action_cb\n",
            "    updates = self.bot.get_updates(\n",
            "  File \"/usr/local/lib/python3.10/dist-packages/telegram/ext/extbot.py\", line 222, in get_updates\n",
            "    updates = super().get_updates(\n",
            "  File \"/usr/local/lib/python3.10/dist-packages/telegram/bot.py\", line 130, in decorator\n",
            "    result = func(*args, **kwargs)\n",
            "  File \"/usr/local/lib/python3.10/dist-packages/telegram/bot.py\", line 2861, in get_updates\n",
            "    self._post(\n",
            "  File \"/usr/local/lib/python3.10/dist-packages/telegram/bot.py\", line 295, in _post\n",
            "    return self.request.post(\n",
            "  File \"/usr/local/lib/python3.10/dist-packages/telegram/utils/request.py\", line 356, in post\n",
            "    result = self._request_wrapper(\n",
            "  File \"/usr/local/lib/python3.10/dist-packages/telegram/utils/request.py\", line 283, in _request_wrapper\n",
            "    raise Conflict(message)\n",
            "telegram.error.Conflict: Conflict: terminated by other getUpdates request; make sure that only one bot instance is running\n",
            "ERROR:telegram.ext.updater:Error while getting Updates: Conflict: terminated by other getUpdates request; make sure that only one bot instance is running\n",
            "ERROR:telegram.ext.dispatcher:No error handlers are registered, logging exception.\n",
            "Traceback (most recent call last):\n",
            "  File \"/usr/local/lib/python3.10/dist-packages/telegram/ext/updater.py\", line 646, in _network_loop_retry\n",
            "    if not action_cb():\n",
            "  File \"/usr/local/lib/python3.10/dist-packages/telegram/ext/updater.py\", line 597, in polling_action_cb\n",
            "    updates = self.bot.get_updates(\n",
            "  File \"/usr/local/lib/python3.10/dist-packages/telegram/ext/extbot.py\", line 222, in get_updates\n",
            "    updates = super().get_updates(\n",
            "  File \"/usr/local/lib/python3.10/dist-packages/telegram/bot.py\", line 130, in decorator\n",
            "    result = func(*args, **kwargs)\n",
            "  File \"/usr/local/lib/python3.10/dist-packages/telegram/bot.py\", line 2861, in get_updates\n",
            "    self._post(\n",
            "  File \"/usr/local/lib/python3.10/dist-packages/telegram/bot.py\", line 295, in _post\n",
            "    return self.request.post(\n",
            "  File \"/usr/local/lib/python3.10/dist-packages/telegram/utils/request.py\", line 356, in post\n",
            "    result = self._request_wrapper(\n",
            "  File \"/usr/local/lib/python3.10/dist-packages/telegram/utils/request.py\", line 283, in _request_wrapper\n",
            "    raise Conflict(message)\n",
            "telegram.error.Conflict: Conflict: terminated by other getUpdates request; make sure that only one bot instance is running\n",
            "ERROR:telegram.ext.updater:Error while getting Updates: Conflict: terminated by other getUpdates request; make sure that only one bot instance is running\n",
            "ERROR:telegram.ext.dispatcher:No error handlers are registered, logging exception.\n",
            "Traceback (most recent call last):\n",
            "  File \"/usr/local/lib/python3.10/dist-packages/telegram/ext/updater.py\", line 646, in _network_loop_retry\n",
            "    if not action_cb():\n",
            "  File \"/usr/local/lib/python3.10/dist-packages/telegram/ext/updater.py\", line 597, in polling_action_cb\n",
            "    updates = self.bot.get_updates(\n",
            "  File \"/usr/local/lib/python3.10/dist-packages/telegram/ext/extbot.py\", line 222, in get_updates\n",
            "    updates = super().get_updates(\n",
            "  File \"/usr/local/lib/python3.10/dist-packages/telegram/bot.py\", line 130, in decorator\n",
            "    result = func(*args, **kwargs)\n",
            "  File \"/usr/local/lib/python3.10/dist-packages/telegram/bot.py\", line 2861, in get_updates\n",
            "    self._post(\n",
            "  File \"/usr/local/lib/python3.10/dist-packages/telegram/bot.py\", line 295, in _post\n",
            "    return self.request.post(\n",
            "  File \"/usr/local/lib/python3.10/dist-packages/telegram/utils/request.py\", line 356, in post\n",
            "    result = self._request_wrapper(\n",
            "  File \"/usr/local/lib/python3.10/dist-packages/telegram/utils/request.py\", line 283, in _request_wrapper\n",
            "    raise Conflict(message)\n",
            "telegram.error.Conflict: Conflict: terminated by other getUpdates request; make sure that only one bot instance is running\n",
            "ERROR:telegram.ext.updater:Error while getting Updates: Conflict: terminated by other getUpdates request; make sure that only one bot instance is running\n",
            "ERROR:telegram.ext.dispatcher:No error handlers are registered, logging exception.\n",
            "Traceback (most recent call last):\n",
            "  File \"/usr/local/lib/python3.10/dist-packages/telegram/ext/updater.py\", line 646, in _network_loop_retry\n",
            "    if not action_cb():\n",
            "  File \"/usr/local/lib/python3.10/dist-packages/telegram/ext/updater.py\", line 597, in polling_action_cb\n",
            "    updates = self.bot.get_updates(\n",
            "  File \"/usr/local/lib/python3.10/dist-packages/telegram/ext/extbot.py\", line 222, in get_updates\n",
            "    updates = super().get_updates(\n",
            "  File \"/usr/local/lib/python3.10/dist-packages/telegram/bot.py\", line 130, in decorator\n",
            "    result = func(*args, **kwargs)\n",
            "  File \"/usr/local/lib/python3.10/dist-packages/telegram/bot.py\", line 2861, in get_updates\n",
            "    self._post(\n",
            "  File \"/usr/local/lib/python3.10/dist-packages/telegram/bot.py\", line 295, in _post\n",
            "    return self.request.post(\n",
            "  File \"/usr/local/lib/python3.10/dist-packages/telegram/utils/request.py\", line 356, in post\n",
            "    result = self._request_wrapper(\n",
            "  File \"/usr/local/lib/python3.10/dist-packages/telegram/utils/request.py\", line 283, in _request_wrapper\n",
            "    raise Conflict(message)\n",
            "telegram.error.Conflict: Conflict: terminated by other getUpdates request; make sure that only one bot instance is running\n",
            "ERROR:telegram.ext.updater:Error while getting Updates: Conflict: terminated by other getUpdates request; make sure that only one bot instance is running\n",
            "ERROR:telegram.ext.dispatcher:No error handlers are registered, logging exception.\n",
            "Traceback (most recent call last):\n",
            "  File \"/usr/local/lib/python3.10/dist-packages/telegram/ext/updater.py\", line 646, in _network_loop_retry\n",
            "    if not action_cb():\n",
            "  File \"/usr/local/lib/python3.10/dist-packages/telegram/ext/updater.py\", line 597, in polling_action_cb\n",
            "    updates = self.bot.get_updates(\n",
            "  File \"/usr/local/lib/python3.10/dist-packages/telegram/ext/extbot.py\", line 222, in get_updates\n",
            "    updates = super().get_updates(\n",
            "  File \"/usr/local/lib/python3.10/dist-packages/telegram/bot.py\", line 130, in decorator\n",
            "    result = func(*args, **kwargs)\n",
            "  File \"/usr/local/lib/python3.10/dist-packages/telegram/bot.py\", line 2861, in get_updates\n",
            "    self._post(\n",
            "  File \"/usr/local/lib/python3.10/dist-packages/telegram/bot.py\", line 295, in _post\n",
            "    return self.request.post(\n",
            "  File \"/usr/local/lib/python3.10/dist-packages/telegram/utils/request.py\", line 356, in post\n",
            "    result = self._request_wrapper(\n",
            "  File \"/usr/local/lib/python3.10/dist-packages/telegram/utils/request.py\", line 283, in _request_wrapper\n",
            "    raise Conflict(message)\n",
            "telegram.error.Conflict: Conflict: terminated by other getUpdates request; make sure that only one bot instance is running\n",
            "ERROR:telegram.ext.updater:Error while getting Updates: Conflict: terminated by other getUpdates request; make sure that only one bot instance is running\n",
            "ERROR:telegram.ext.dispatcher:No error handlers are registered, logging exception.\n",
            "Traceback (most recent call last):\n",
            "  File \"/usr/local/lib/python3.10/dist-packages/telegram/ext/updater.py\", line 646, in _network_loop_retry\n",
            "    if not action_cb():\n",
            "  File \"/usr/local/lib/python3.10/dist-packages/telegram/ext/updater.py\", line 597, in polling_action_cb\n",
            "    updates = self.bot.get_updates(\n",
            "  File \"/usr/local/lib/python3.10/dist-packages/telegram/ext/extbot.py\", line 222, in get_updates\n",
            "    updates = super().get_updates(\n",
            "  File \"/usr/local/lib/python3.10/dist-packages/telegram/bot.py\", line 130, in decorator\n",
            "    result = func(*args, **kwargs)\n",
            "  File \"/usr/local/lib/python3.10/dist-packages/telegram/bot.py\", line 2861, in get_updates\n",
            "    self._post(\n",
            "  File \"/usr/local/lib/python3.10/dist-packages/telegram/bot.py\", line 295, in _post\n",
            "    return self.request.post(\n",
            "  File \"/usr/local/lib/python3.10/dist-packages/telegram/utils/request.py\", line 356, in post\n",
            "    result = self._request_wrapper(\n",
            "  File \"/usr/local/lib/python3.10/dist-packages/telegram/utils/request.py\", line 283, in _request_wrapper\n",
            "    raise Conflict(message)\n",
            "telegram.error.Conflict: Conflict: terminated by other getUpdates request; make sure that only one bot instance is running\n",
            "ERROR:telegram.ext.updater:Error while getting Updates: Conflict: terminated by other getUpdates request; make sure that only one bot instance is running\n",
            "ERROR:telegram.ext.dispatcher:No error handlers are registered, logging exception.\n",
            "Traceback (most recent call last):\n",
            "  File \"/usr/local/lib/python3.10/dist-packages/telegram/ext/updater.py\", line 646, in _network_loop_retry\n",
            "    if not action_cb():\n",
            "  File \"/usr/local/lib/python3.10/dist-packages/telegram/ext/updater.py\", line 597, in polling_action_cb\n",
            "    updates = self.bot.get_updates(\n",
            "  File \"/usr/local/lib/python3.10/dist-packages/telegram/ext/extbot.py\", line 222, in get_updates\n",
            "    updates = super().get_updates(\n",
            "  File \"/usr/local/lib/python3.10/dist-packages/telegram/bot.py\", line 130, in decorator\n",
            "    result = func(*args, **kwargs)\n",
            "  File \"/usr/local/lib/python3.10/dist-packages/telegram/bot.py\", line 2861, in get_updates\n",
            "    self._post(\n",
            "  File \"/usr/local/lib/python3.10/dist-packages/telegram/bot.py\", line 295, in _post\n",
            "    return self.request.post(\n",
            "  File \"/usr/local/lib/python3.10/dist-packages/telegram/utils/request.py\", line 356, in post\n",
            "    result = self._request_wrapper(\n",
            "  File \"/usr/local/lib/python3.10/dist-packages/telegram/utils/request.py\", line 283, in _request_wrapper\n",
            "    raise Conflict(message)\n",
            "telegram.error.Conflict: Conflict: terminated by other getUpdates request; make sure that only one bot instance is running\n",
            "ERROR:telegram.ext.updater:Error while getting Updates: Conflict: terminated by other getUpdates request; make sure that only one bot instance is running\n",
            "ERROR:telegram.ext.dispatcher:No error handlers are registered, logging exception.\n",
            "Traceback (most recent call last):\n",
            "  File \"/usr/local/lib/python3.10/dist-packages/telegram/ext/updater.py\", line 646, in _network_loop_retry\n",
            "    if not action_cb():\n",
            "  File \"/usr/local/lib/python3.10/dist-packages/telegram/ext/updater.py\", line 597, in polling_action_cb\n",
            "    updates = self.bot.get_updates(\n",
            "  File \"/usr/local/lib/python3.10/dist-packages/telegram/ext/extbot.py\", line 222, in get_updates\n",
            "    updates = super().get_updates(\n",
            "  File \"/usr/local/lib/python3.10/dist-packages/telegram/bot.py\", line 130, in decorator\n",
            "    result = func(*args, **kwargs)\n",
            "  File \"/usr/local/lib/python3.10/dist-packages/telegram/bot.py\", line 2861, in get_updates\n",
            "    self._post(\n",
            "  File \"/usr/local/lib/python3.10/dist-packages/telegram/bot.py\", line 295, in _post\n",
            "    return self.request.post(\n",
            "  File \"/usr/local/lib/python3.10/dist-packages/telegram/utils/request.py\", line 356, in post\n",
            "    result = self._request_wrapper(\n",
            "  File \"/usr/local/lib/python3.10/dist-packages/telegram/utils/request.py\", line 283, in _request_wrapper\n",
            "    raise Conflict(message)\n",
            "telegram.error.Conflict: Conflict: terminated by other getUpdates request; make sure that only one bot instance is running\n",
            "ERROR:telegram.ext.updater:Error while getting Updates: Conflict: terminated by other getUpdates request; make sure that only one bot instance is running\n",
            "ERROR:telegram.ext.dispatcher:No error handlers are registered, logging exception.\n",
            "Traceback (most recent call last):\n",
            "  File \"/usr/local/lib/python3.10/dist-packages/telegram/ext/updater.py\", line 646, in _network_loop_retry\n",
            "    if not action_cb():\n",
            "  File \"/usr/local/lib/python3.10/dist-packages/telegram/ext/updater.py\", line 597, in polling_action_cb\n",
            "    updates = self.bot.get_updates(\n",
            "  File \"/usr/local/lib/python3.10/dist-packages/telegram/ext/extbot.py\", line 222, in get_updates\n",
            "    updates = super().get_updates(\n",
            "  File \"/usr/local/lib/python3.10/dist-packages/telegram/bot.py\", line 130, in decorator\n",
            "    result = func(*args, **kwargs)\n",
            "  File \"/usr/local/lib/python3.10/dist-packages/telegram/bot.py\", line 2861, in get_updates\n",
            "    self._post(\n",
            "  File \"/usr/local/lib/python3.10/dist-packages/telegram/bot.py\", line 295, in _post\n",
            "    return self.request.post(\n",
            "  File \"/usr/local/lib/python3.10/dist-packages/telegram/utils/request.py\", line 356, in post\n",
            "    result = self._request_wrapper(\n",
            "  File \"/usr/local/lib/python3.10/dist-packages/telegram/utils/request.py\", line 283, in _request_wrapper\n",
            "    raise Conflict(message)\n",
            "telegram.error.Conflict: Conflict: terminated by other getUpdates request; make sure that only one bot instance is running\n",
            "ERROR:telegram.ext.updater:Error while getting Updates: Conflict: terminated by other getUpdates request; make sure that only one bot instance is running\n",
            "ERROR:telegram.ext.dispatcher:No error handlers are registered, logging exception.\n",
            "Traceback (most recent call last):\n",
            "  File \"/usr/local/lib/python3.10/dist-packages/telegram/ext/updater.py\", line 646, in _network_loop_retry\n",
            "    if not action_cb():\n",
            "  File \"/usr/local/lib/python3.10/dist-packages/telegram/ext/updater.py\", line 597, in polling_action_cb\n",
            "    updates = self.bot.get_updates(\n",
            "  File \"/usr/local/lib/python3.10/dist-packages/telegram/ext/extbot.py\", line 222, in get_updates\n",
            "    updates = super().get_updates(\n",
            "  File \"/usr/local/lib/python3.10/dist-packages/telegram/bot.py\", line 130, in decorator\n",
            "    result = func(*args, **kwargs)\n",
            "  File \"/usr/local/lib/python3.10/dist-packages/telegram/bot.py\", line 2861, in get_updates\n",
            "    self._post(\n",
            "  File \"/usr/local/lib/python3.10/dist-packages/telegram/bot.py\", line 295, in _post\n",
            "    return self.request.post(\n",
            "  File \"/usr/local/lib/python3.10/dist-packages/telegram/utils/request.py\", line 356, in post\n",
            "    result = self._request_wrapper(\n",
            "  File \"/usr/local/lib/python3.10/dist-packages/telegram/utils/request.py\", line 283, in _request_wrapper\n",
            "    raise Conflict(message)\n",
            "telegram.error.Conflict: Conflict: terminated by other getUpdates request; make sure that only one bot instance is running\n",
            "ERROR:telegram.ext.updater:Error while getting Updates: Conflict: terminated by other getUpdates request; make sure that only one bot instance is running\n",
            "ERROR:telegram.ext.dispatcher:No error handlers are registered, logging exception.\n",
            "Traceback (most recent call last):\n",
            "  File \"/usr/local/lib/python3.10/dist-packages/telegram/ext/updater.py\", line 646, in _network_loop_retry\n",
            "    if not action_cb():\n",
            "  File \"/usr/local/lib/python3.10/dist-packages/telegram/ext/updater.py\", line 597, in polling_action_cb\n",
            "    updates = self.bot.get_updates(\n",
            "  File \"/usr/local/lib/python3.10/dist-packages/telegram/ext/extbot.py\", line 222, in get_updates\n",
            "    updates = super().get_updates(\n",
            "  File \"/usr/local/lib/python3.10/dist-packages/telegram/bot.py\", line 130, in decorator\n",
            "    result = func(*args, **kwargs)\n",
            "  File \"/usr/local/lib/python3.10/dist-packages/telegram/bot.py\", line 2861, in get_updates\n",
            "    self._post(\n",
            "  File \"/usr/local/lib/python3.10/dist-packages/telegram/bot.py\", line 295, in _post\n",
            "    return self.request.post(\n",
            "  File \"/usr/local/lib/python3.10/dist-packages/telegram/utils/request.py\", line 356, in post\n",
            "    result = self._request_wrapper(\n",
            "  File \"/usr/local/lib/python3.10/dist-packages/telegram/utils/request.py\", line 283, in _request_wrapper\n",
            "    raise Conflict(message)\n",
            "telegram.error.Conflict: Conflict: terminated by other getUpdates request; make sure that only one bot instance is running\n",
            "ERROR:telegram.ext.updater:Error while getting Updates: Conflict: terminated by other getUpdates request; make sure that only one bot instance is running\n",
            "ERROR:telegram.ext.dispatcher:No error handlers are registered, logging exception.\n",
            "Traceback (most recent call last):\n",
            "  File \"/usr/local/lib/python3.10/dist-packages/telegram/ext/updater.py\", line 646, in _network_loop_retry\n",
            "    if not action_cb():\n",
            "  File \"/usr/local/lib/python3.10/dist-packages/telegram/ext/updater.py\", line 597, in polling_action_cb\n",
            "    updates = self.bot.get_updates(\n",
            "  File \"/usr/local/lib/python3.10/dist-packages/telegram/ext/extbot.py\", line 222, in get_updates\n",
            "    updates = super().get_updates(\n",
            "  File \"/usr/local/lib/python3.10/dist-packages/telegram/bot.py\", line 130, in decorator\n",
            "    result = func(*args, **kwargs)\n",
            "  File \"/usr/local/lib/python3.10/dist-packages/telegram/bot.py\", line 2861, in get_updates\n",
            "    self._post(\n",
            "  File \"/usr/local/lib/python3.10/dist-packages/telegram/bot.py\", line 295, in _post\n",
            "    return self.request.post(\n",
            "  File \"/usr/local/lib/python3.10/dist-packages/telegram/utils/request.py\", line 356, in post\n",
            "    result = self._request_wrapper(\n",
            "  File \"/usr/local/lib/python3.10/dist-packages/telegram/utils/request.py\", line 283, in _request_wrapper\n",
            "    raise Conflict(message)\n",
            "telegram.error.Conflict: Conflict: terminated by other getUpdates request; make sure that only one bot instance is running\n",
            "ERROR:telegram.ext.updater:Error while getting Updates: Conflict: terminated by other getUpdates request; make sure that only one bot instance is running\n",
            "ERROR:telegram.ext.dispatcher:No error handlers are registered, logging exception.\n",
            "Traceback (most recent call last):\n",
            "  File \"/usr/local/lib/python3.10/dist-packages/telegram/ext/updater.py\", line 646, in _network_loop_retry\n",
            "    if not action_cb():\n",
            "  File \"/usr/local/lib/python3.10/dist-packages/telegram/ext/updater.py\", line 597, in polling_action_cb\n",
            "    updates = self.bot.get_updates(\n",
            "  File \"/usr/local/lib/python3.10/dist-packages/telegram/ext/extbot.py\", line 222, in get_updates\n",
            "    updates = super().get_updates(\n",
            "  File \"/usr/local/lib/python3.10/dist-packages/telegram/bot.py\", line 130, in decorator\n",
            "    result = func(*args, **kwargs)\n",
            "  File \"/usr/local/lib/python3.10/dist-packages/telegram/bot.py\", line 2861, in get_updates\n",
            "    self._post(\n",
            "  File \"/usr/local/lib/python3.10/dist-packages/telegram/bot.py\", line 295, in _post\n",
            "    return self.request.post(\n",
            "  File \"/usr/local/lib/python3.10/dist-packages/telegram/utils/request.py\", line 356, in post\n",
            "    result = self._request_wrapper(\n",
            "  File \"/usr/local/lib/python3.10/dist-packages/telegram/utils/request.py\", line 283, in _request_wrapper\n",
            "    raise Conflict(message)\n",
            "telegram.error.Conflict: Conflict: terminated by other getUpdates request; make sure that only one bot instance is running\n",
            "ERROR:telegram.ext.updater:Error while getting Updates: Conflict: terminated by other getUpdates request; make sure that only one bot instance is running\n",
            "ERROR:telegram.ext.dispatcher:No error handlers are registered, logging exception.\n",
            "Traceback (most recent call last):\n",
            "  File \"/usr/local/lib/python3.10/dist-packages/telegram/ext/updater.py\", line 646, in _network_loop_retry\n",
            "    if not action_cb():\n",
            "  File \"/usr/local/lib/python3.10/dist-packages/telegram/ext/updater.py\", line 597, in polling_action_cb\n",
            "    updates = self.bot.get_updates(\n",
            "  File \"/usr/local/lib/python3.10/dist-packages/telegram/ext/extbot.py\", line 222, in get_updates\n",
            "    updates = super().get_updates(\n",
            "  File \"/usr/local/lib/python3.10/dist-packages/telegram/bot.py\", line 130, in decorator\n",
            "    result = func(*args, **kwargs)\n",
            "  File \"/usr/local/lib/python3.10/dist-packages/telegram/bot.py\", line 2861, in get_updates\n",
            "    self._post(\n",
            "  File \"/usr/local/lib/python3.10/dist-packages/telegram/bot.py\", line 295, in _post\n",
            "    return self.request.post(\n",
            "  File \"/usr/local/lib/python3.10/dist-packages/telegram/utils/request.py\", line 356, in post\n",
            "    result = self._request_wrapper(\n",
            "  File \"/usr/local/lib/python3.10/dist-packages/telegram/utils/request.py\", line 283, in _request_wrapper\n",
            "    raise Conflict(message)\n",
            "telegram.error.Conflict: Conflict: terminated by other getUpdates request; make sure that only one bot instance is running\n",
            "ERROR:telegram.ext.updater:Error while getting Updates: Conflict: terminated by other getUpdates request; make sure that only one bot instance is running\n",
            "ERROR:telegram.ext.dispatcher:No error handlers are registered, logging exception.\n",
            "Traceback (most recent call last):\n",
            "  File \"/usr/local/lib/python3.10/dist-packages/telegram/ext/updater.py\", line 646, in _network_loop_retry\n",
            "    if not action_cb():\n",
            "  File \"/usr/local/lib/python3.10/dist-packages/telegram/ext/updater.py\", line 597, in polling_action_cb\n",
            "    updates = self.bot.get_updates(\n",
            "  File \"/usr/local/lib/python3.10/dist-packages/telegram/ext/extbot.py\", line 222, in get_updates\n",
            "    updates = super().get_updates(\n",
            "  File \"/usr/local/lib/python3.10/dist-packages/telegram/bot.py\", line 130, in decorator\n",
            "    result = func(*args, **kwargs)\n",
            "  File \"/usr/local/lib/python3.10/dist-packages/telegram/bot.py\", line 2861, in get_updates\n",
            "    self._post(\n",
            "  File \"/usr/local/lib/python3.10/dist-packages/telegram/bot.py\", line 295, in _post\n",
            "    return self.request.post(\n",
            "  File \"/usr/local/lib/python3.10/dist-packages/telegram/utils/request.py\", line 356, in post\n",
            "    result = self._request_wrapper(\n",
            "  File \"/usr/local/lib/python3.10/dist-packages/telegram/utils/request.py\", line 283, in _request_wrapper\n",
            "    raise Conflict(message)\n",
            "telegram.error.Conflict: Conflict: terminated by other getUpdates request; make sure that only one bot instance is running\n",
            "ERROR:telegram.ext.updater:Error while getting Updates: Conflict: terminated by other getUpdates request; make sure that only one bot instance is running\n",
            "ERROR:telegram.ext.dispatcher:No error handlers are registered, logging exception.\n",
            "Traceback (most recent call last):\n",
            "  File \"/usr/local/lib/python3.10/dist-packages/telegram/ext/updater.py\", line 646, in _network_loop_retry\n",
            "    if not action_cb():\n",
            "  File \"/usr/local/lib/python3.10/dist-packages/telegram/ext/updater.py\", line 597, in polling_action_cb\n",
            "    updates = self.bot.get_updates(\n",
            "  File \"/usr/local/lib/python3.10/dist-packages/telegram/ext/extbot.py\", line 222, in get_updates\n",
            "    updates = super().get_updates(\n",
            "  File \"/usr/local/lib/python3.10/dist-packages/telegram/bot.py\", line 130, in decorator\n",
            "    result = func(*args, **kwargs)\n",
            "  File \"/usr/local/lib/python3.10/dist-packages/telegram/bot.py\", line 2861, in get_updates\n",
            "    self._post(\n",
            "  File \"/usr/local/lib/python3.10/dist-packages/telegram/bot.py\", line 295, in _post\n",
            "    return self.request.post(\n",
            "  File \"/usr/local/lib/python3.10/dist-packages/telegram/utils/request.py\", line 356, in post\n",
            "    result = self._request_wrapper(\n",
            "  File \"/usr/local/lib/python3.10/dist-packages/telegram/utils/request.py\", line 283, in _request_wrapper\n",
            "    raise Conflict(message)\n",
            "telegram.error.Conflict: Conflict: terminated by other getUpdates request; make sure that only one bot instance is running\n",
            "ERROR:telegram.ext.updater:Error while getting Updates: Conflict: terminated by other getUpdates request; make sure that only one bot instance is running\n",
            "ERROR:telegram.ext.dispatcher:No error handlers are registered, logging exception.\n",
            "Traceback (most recent call last):\n",
            "  File \"/usr/local/lib/python3.10/dist-packages/telegram/ext/updater.py\", line 646, in _network_loop_retry\n",
            "    if not action_cb():\n",
            "  File \"/usr/local/lib/python3.10/dist-packages/telegram/ext/updater.py\", line 597, in polling_action_cb\n",
            "    updates = self.bot.get_updates(\n",
            "  File \"/usr/local/lib/python3.10/dist-packages/telegram/ext/extbot.py\", line 222, in get_updates\n",
            "    updates = super().get_updates(\n",
            "  File \"/usr/local/lib/python3.10/dist-packages/telegram/bot.py\", line 130, in decorator\n",
            "    result = func(*args, **kwargs)\n",
            "  File \"/usr/local/lib/python3.10/dist-packages/telegram/bot.py\", line 2861, in get_updates\n",
            "    self._post(\n",
            "  File \"/usr/local/lib/python3.10/dist-packages/telegram/bot.py\", line 295, in _post\n",
            "    return self.request.post(\n",
            "  File \"/usr/local/lib/python3.10/dist-packages/telegram/utils/request.py\", line 356, in post\n",
            "    result = self._request_wrapper(\n",
            "  File \"/usr/local/lib/python3.10/dist-packages/telegram/utils/request.py\", line 283, in _request_wrapper\n",
            "    raise Conflict(message)\n",
            "telegram.error.Conflict: Conflict: terminated by other getUpdates request; make sure that only one bot instance is running\n",
            "ERROR:telegram.ext.updater:Error while getting Updates: Conflict: terminated by other getUpdates request; make sure that only one bot instance is running\n",
            "ERROR:telegram.ext.dispatcher:No error handlers are registered, logging exception.\n",
            "Traceback (most recent call last):\n",
            "  File \"/usr/local/lib/python3.10/dist-packages/telegram/ext/updater.py\", line 646, in _network_loop_retry\n",
            "    if not action_cb():\n",
            "  File \"/usr/local/lib/python3.10/dist-packages/telegram/ext/updater.py\", line 597, in polling_action_cb\n",
            "    updates = self.bot.get_updates(\n",
            "  File \"/usr/local/lib/python3.10/dist-packages/telegram/ext/extbot.py\", line 222, in get_updates\n",
            "    updates = super().get_updates(\n",
            "  File \"/usr/local/lib/python3.10/dist-packages/telegram/bot.py\", line 130, in decorator\n",
            "    result = func(*args, **kwargs)\n",
            "  File \"/usr/local/lib/python3.10/dist-packages/telegram/bot.py\", line 2861, in get_updates\n",
            "    self._post(\n",
            "  File \"/usr/local/lib/python3.10/dist-packages/telegram/bot.py\", line 295, in _post\n",
            "    return self.request.post(\n",
            "  File \"/usr/local/lib/python3.10/dist-packages/telegram/utils/request.py\", line 356, in post\n",
            "    result = self._request_wrapper(\n",
            "  File \"/usr/local/lib/python3.10/dist-packages/telegram/utils/request.py\", line 283, in _request_wrapper\n",
            "    raise Conflict(message)\n",
            "telegram.error.Conflict: Conflict: terminated by other getUpdates request; make sure that only one bot instance is running\n",
            "ERROR:telegram.ext.updater:Error while getting Updates: Conflict: terminated by other getUpdates request; make sure that only one bot instance is running\n",
            "ERROR:telegram.ext.dispatcher:No error handlers are registered, logging exception.\n",
            "Traceback (most recent call last):\n",
            "  File \"/usr/local/lib/python3.10/dist-packages/telegram/ext/updater.py\", line 646, in _network_loop_retry\n",
            "    if not action_cb():\n",
            "  File \"/usr/local/lib/python3.10/dist-packages/telegram/ext/updater.py\", line 597, in polling_action_cb\n",
            "    updates = self.bot.get_updates(\n",
            "  File \"/usr/local/lib/python3.10/dist-packages/telegram/ext/extbot.py\", line 222, in get_updates\n",
            "    updates = super().get_updates(\n",
            "  File \"/usr/local/lib/python3.10/dist-packages/telegram/bot.py\", line 130, in decorator\n",
            "    result = func(*args, **kwargs)\n",
            "  File \"/usr/local/lib/python3.10/dist-packages/telegram/bot.py\", line 2861, in get_updates\n",
            "    self._post(\n",
            "  File \"/usr/local/lib/python3.10/dist-packages/telegram/bot.py\", line 295, in _post\n",
            "    return self.request.post(\n",
            "  File \"/usr/local/lib/python3.10/dist-packages/telegram/utils/request.py\", line 356, in post\n",
            "    result = self._request_wrapper(\n",
            "  File \"/usr/local/lib/python3.10/dist-packages/telegram/utils/request.py\", line 283, in _request_wrapper\n",
            "    raise Conflict(message)\n",
            "telegram.error.Conflict: Conflict: terminated by other getUpdates request; make sure that only one bot instance is running\n",
            "ERROR:telegram.ext.updater:Error while getting Updates: Conflict: terminated by other getUpdates request; make sure that only one bot instance is running\n",
            "ERROR:telegram.ext.dispatcher:No error handlers are registered, logging exception.\n",
            "Traceback (most recent call last):\n",
            "  File \"/usr/local/lib/python3.10/dist-packages/telegram/ext/updater.py\", line 646, in _network_loop_retry\n",
            "    if not action_cb():\n",
            "  File \"/usr/local/lib/python3.10/dist-packages/telegram/ext/updater.py\", line 597, in polling_action_cb\n",
            "    updates = self.bot.get_updates(\n",
            "  File \"/usr/local/lib/python3.10/dist-packages/telegram/ext/extbot.py\", line 222, in get_updates\n",
            "    updates = super().get_updates(\n",
            "  File \"/usr/local/lib/python3.10/dist-packages/telegram/bot.py\", line 130, in decorator\n",
            "    result = func(*args, **kwargs)\n",
            "  File \"/usr/local/lib/python3.10/dist-packages/telegram/bot.py\", line 2861, in get_updates\n",
            "    self._post(\n",
            "  File \"/usr/local/lib/python3.10/dist-packages/telegram/bot.py\", line 295, in _post\n",
            "    return self.request.post(\n",
            "  File \"/usr/local/lib/python3.10/dist-packages/telegram/utils/request.py\", line 356, in post\n",
            "    result = self._request_wrapper(\n",
            "  File \"/usr/local/lib/python3.10/dist-packages/telegram/utils/request.py\", line 283, in _request_wrapper\n",
            "    raise Conflict(message)\n",
            "telegram.error.Conflict: Conflict: terminated by other getUpdates request; make sure that only one bot instance is running\n",
            "ERROR:telegram.ext.updater:Error while getting Updates: Conflict: terminated by other getUpdates request; make sure that only one bot instance is running\n",
            "ERROR:telegram.ext.dispatcher:No error handlers are registered, logging exception.\n",
            "Traceback (most recent call last):\n",
            "  File \"/usr/local/lib/python3.10/dist-packages/telegram/ext/updater.py\", line 646, in _network_loop_retry\n",
            "    if not action_cb():\n",
            "  File \"/usr/local/lib/python3.10/dist-packages/telegram/ext/updater.py\", line 597, in polling_action_cb\n",
            "    updates = self.bot.get_updates(\n",
            "  File \"/usr/local/lib/python3.10/dist-packages/telegram/ext/extbot.py\", line 222, in get_updates\n",
            "    updates = super().get_updates(\n",
            "  File \"/usr/local/lib/python3.10/dist-packages/telegram/bot.py\", line 130, in decorator\n",
            "    result = func(*args, **kwargs)\n",
            "  File \"/usr/local/lib/python3.10/dist-packages/telegram/bot.py\", line 2861, in get_updates\n",
            "    self._post(\n",
            "  File \"/usr/local/lib/python3.10/dist-packages/telegram/bot.py\", line 295, in _post\n",
            "    return self.request.post(\n",
            "  File \"/usr/local/lib/python3.10/dist-packages/telegram/utils/request.py\", line 356, in post\n",
            "    result = self._request_wrapper(\n",
            "  File \"/usr/local/lib/python3.10/dist-packages/telegram/utils/request.py\", line 283, in _request_wrapper\n",
            "    raise Conflict(message)\n",
            "telegram.error.Conflict: Conflict: terminated by other getUpdates request; make sure that only one bot instance is running\n",
            "ERROR:telegram.ext.updater:Error while getting Updates: Conflict: terminated by other getUpdates request; make sure that only one bot instance is running\n",
            "ERROR:telegram.ext.dispatcher:No error handlers are registered, logging exception.\n",
            "Traceback (most recent call last):\n",
            "  File \"/usr/local/lib/python3.10/dist-packages/telegram/ext/updater.py\", line 646, in _network_loop_retry\n",
            "    if not action_cb():\n",
            "  File \"/usr/local/lib/python3.10/dist-packages/telegram/ext/updater.py\", line 597, in polling_action_cb\n",
            "    updates = self.bot.get_updates(\n",
            "  File \"/usr/local/lib/python3.10/dist-packages/telegram/ext/extbot.py\", line 222, in get_updates\n",
            "    updates = super().get_updates(\n",
            "  File \"/usr/local/lib/python3.10/dist-packages/telegram/bot.py\", line 130, in decorator\n",
            "    result = func(*args, **kwargs)\n",
            "  File \"/usr/local/lib/python3.10/dist-packages/telegram/bot.py\", line 2861, in get_updates\n",
            "    self._post(\n",
            "  File \"/usr/local/lib/python3.10/dist-packages/telegram/bot.py\", line 295, in _post\n",
            "    return self.request.post(\n",
            "  File \"/usr/local/lib/python3.10/dist-packages/telegram/utils/request.py\", line 356, in post\n",
            "    result = self._request_wrapper(\n",
            "  File \"/usr/local/lib/python3.10/dist-packages/telegram/utils/request.py\", line 283, in _request_wrapper\n",
            "    raise Conflict(message)\n",
            "telegram.error.Conflict: Conflict: terminated by other getUpdates request; make sure that only one bot instance is running\n",
            "ERROR:telegram.ext.updater:Error while getting Updates: Conflict: terminated by other getUpdates request; make sure that only one bot instance is running\n",
            "ERROR:telegram.ext.dispatcher:No error handlers are registered, logging exception.\n",
            "Traceback (most recent call last):\n",
            "  File \"/usr/local/lib/python3.10/dist-packages/telegram/ext/updater.py\", line 646, in _network_loop_retry\n",
            "    if not action_cb():\n",
            "  File \"/usr/local/lib/python3.10/dist-packages/telegram/ext/updater.py\", line 597, in polling_action_cb\n",
            "    updates = self.bot.get_updates(\n",
            "  File \"/usr/local/lib/python3.10/dist-packages/telegram/ext/extbot.py\", line 222, in get_updates\n",
            "    updates = super().get_updates(\n",
            "  File \"/usr/local/lib/python3.10/dist-packages/telegram/bot.py\", line 130, in decorator\n",
            "    result = func(*args, **kwargs)\n",
            "  File \"/usr/local/lib/python3.10/dist-packages/telegram/bot.py\", line 2861, in get_updates\n",
            "    self._post(\n",
            "  File \"/usr/local/lib/python3.10/dist-packages/telegram/bot.py\", line 295, in _post\n",
            "    return self.request.post(\n",
            "  File \"/usr/local/lib/python3.10/dist-packages/telegram/utils/request.py\", line 356, in post\n",
            "    result = self._request_wrapper(\n",
            "  File \"/usr/local/lib/python3.10/dist-packages/telegram/utils/request.py\", line 283, in _request_wrapper\n",
            "    raise Conflict(message)\n",
            "telegram.error.Conflict: Conflict: terminated by other getUpdates request; make sure that only one bot instance is running\n",
            "ERROR:telegram.ext.updater:Error while getting Updates: Conflict: terminated by other getUpdates request; make sure that only one bot instance is running\n",
            "ERROR:telegram.ext.dispatcher:No error handlers are registered, logging exception.\n",
            "Traceback (most recent call last):\n",
            "  File \"/usr/local/lib/python3.10/dist-packages/telegram/ext/updater.py\", line 646, in _network_loop_retry\n",
            "    if not action_cb():\n",
            "  File \"/usr/local/lib/python3.10/dist-packages/telegram/ext/updater.py\", line 597, in polling_action_cb\n",
            "    updates = self.bot.get_updates(\n",
            "  File \"/usr/local/lib/python3.10/dist-packages/telegram/ext/extbot.py\", line 222, in get_updates\n",
            "    updates = super().get_updates(\n",
            "  File \"/usr/local/lib/python3.10/dist-packages/telegram/bot.py\", line 130, in decorator\n",
            "    result = func(*args, **kwargs)\n",
            "  File \"/usr/local/lib/python3.10/dist-packages/telegram/bot.py\", line 2861, in get_updates\n",
            "    self._post(\n",
            "  File \"/usr/local/lib/python3.10/dist-packages/telegram/bot.py\", line 295, in _post\n",
            "    return self.request.post(\n",
            "  File \"/usr/local/lib/python3.10/dist-packages/telegram/utils/request.py\", line 356, in post\n",
            "    result = self._request_wrapper(\n",
            "  File \"/usr/local/lib/python3.10/dist-packages/telegram/utils/request.py\", line 283, in _request_wrapper\n",
            "    raise Conflict(message)\n",
            "telegram.error.Conflict: Conflict: terminated by other getUpdates request; make sure that only one bot instance is running\n",
            "ERROR:telegram.ext.updater:Error while getting Updates: Conflict: terminated by other getUpdates request; make sure that only one bot instance is running\n",
            "ERROR:telegram.ext.dispatcher:No error handlers are registered, logging exception.\n",
            "Traceback (most recent call last):\n",
            "  File \"/usr/local/lib/python3.10/dist-packages/telegram/ext/updater.py\", line 646, in _network_loop_retry\n",
            "    if not action_cb():\n",
            "  File \"/usr/local/lib/python3.10/dist-packages/telegram/ext/updater.py\", line 597, in polling_action_cb\n",
            "    updates = self.bot.get_updates(\n",
            "  File \"/usr/local/lib/python3.10/dist-packages/telegram/ext/extbot.py\", line 222, in get_updates\n",
            "    updates = super().get_updates(\n",
            "  File \"/usr/local/lib/python3.10/dist-packages/telegram/bot.py\", line 130, in decorator\n",
            "    result = func(*args, **kwargs)\n",
            "  File \"/usr/local/lib/python3.10/dist-packages/telegram/bot.py\", line 2861, in get_updates\n",
            "    self._post(\n",
            "  File \"/usr/local/lib/python3.10/dist-packages/telegram/bot.py\", line 295, in _post\n",
            "    return self.request.post(\n",
            "  File \"/usr/local/lib/python3.10/dist-packages/telegram/utils/request.py\", line 356, in post\n",
            "    result = self._request_wrapper(\n",
            "  File \"/usr/local/lib/python3.10/dist-packages/telegram/utils/request.py\", line 283, in _request_wrapper\n",
            "    raise Conflict(message)\n",
            "telegram.error.Conflict: Conflict: terminated by other getUpdates request; make sure that only one bot instance is running\n",
            "ERROR:telegram.ext.updater:Error while getting Updates: Conflict: terminated by other getUpdates request; make sure that only one bot instance is running\n",
            "ERROR:telegram.ext.dispatcher:No error handlers are registered, logging exception.\n",
            "Traceback (most recent call last):\n",
            "  File \"/usr/local/lib/python3.10/dist-packages/telegram/ext/updater.py\", line 646, in _network_loop_retry\n",
            "    if not action_cb():\n",
            "  File \"/usr/local/lib/python3.10/dist-packages/telegram/ext/updater.py\", line 597, in polling_action_cb\n",
            "    updates = self.bot.get_updates(\n",
            "  File \"/usr/local/lib/python3.10/dist-packages/telegram/ext/extbot.py\", line 222, in get_updates\n",
            "    updates = super().get_updates(\n",
            "  File \"/usr/local/lib/python3.10/dist-packages/telegram/bot.py\", line 130, in decorator\n",
            "    result = func(*args, **kwargs)\n",
            "  File \"/usr/local/lib/python3.10/dist-packages/telegram/bot.py\", line 2861, in get_updates\n",
            "    self._post(\n",
            "  File \"/usr/local/lib/python3.10/dist-packages/telegram/bot.py\", line 295, in _post\n",
            "    return self.request.post(\n",
            "  File \"/usr/local/lib/python3.10/dist-packages/telegram/utils/request.py\", line 356, in post\n",
            "    result = self._request_wrapper(\n",
            "  File \"/usr/local/lib/python3.10/dist-packages/telegram/utils/request.py\", line 283, in _request_wrapper\n",
            "    raise Conflict(message)\n",
            "telegram.error.Conflict: Conflict: terminated by other getUpdates request; make sure that only one bot instance is running\n",
            "ERROR:telegram.ext.updater:Error while getting Updates: Conflict: terminated by other getUpdates request; make sure that only one bot instance is running\n",
            "ERROR:telegram.ext.dispatcher:No error handlers are registered, logging exception.\n",
            "Traceback (most recent call last):\n",
            "  File \"/usr/local/lib/python3.10/dist-packages/telegram/ext/updater.py\", line 646, in _network_loop_retry\n",
            "    if not action_cb():\n",
            "  File \"/usr/local/lib/python3.10/dist-packages/telegram/ext/updater.py\", line 597, in polling_action_cb\n",
            "    updates = self.bot.get_updates(\n",
            "  File \"/usr/local/lib/python3.10/dist-packages/telegram/ext/extbot.py\", line 222, in get_updates\n",
            "    updates = super().get_updates(\n",
            "  File \"/usr/local/lib/python3.10/dist-packages/telegram/bot.py\", line 130, in decorator\n",
            "    result = func(*args, **kwargs)\n",
            "  File \"/usr/local/lib/python3.10/dist-packages/telegram/bot.py\", line 2861, in get_updates\n",
            "    self._post(\n",
            "  File \"/usr/local/lib/python3.10/dist-packages/telegram/bot.py\", line 295, in _post\n",
            "    return self.request.post(\n",
            "  File \"/usr/local/lib/python3.10/dist-packages/telegram/utils/request.py\", line 356, in post\n",
            "    result = self._request_wrapper(\n",
            "  File \"/usr/local/lib/python3.10/dist-packages/telegram/utils/request.py\", line 283, in _request_wrapper\n",
            "    raise Conflict(message)\n",
            "telegram.error.Conflict: Conflict: terminated by other getUpdates request; make sure that only one bot instance is running\n",
            "ERROR:telegram.ext.updater:Error while getting Updates: Conflict: terminated by other getUpdates request; make sure that only one bot instance is running\n",
            "ERROR:telegram.ext.dispatcher:No error handlers are registered, logging exception.\n",
            "Traceback (most recent call last):\n",
            "  File \"/usr/local/lib/python3.10/dist-packages/telegram/ext/updater.py\", line 646, in _network_loop_retry\n",
            "    if not action_cb():\n",
            "  File \"/usr/local/lib/python3.10/dist-packages/telegram/ext/updater.py\", line 597, in polling_action_cb\n",
            "    updates = self.bot.get_updates(\n",
            "  File \"/usr/local/lib/python3.10/dist-packages/telegram/ext/extbot.py\", line 222, in get_updates\n",
            "    updates = super().get_updates(\n",
            "  File \"/usr/local/lib/python3.10/dist-packages/telegram/bot.py\", line 130, in decorator\n",
            "    result = func(*args, **kwargs)\n",
            "  File \"/usr/local/lib/python3.10/dist-packages/telegram/bot.py\", line 2861, in get_updates\n",
            "    self._post(\n",
            "  File \"/usr/local/lib/python3.10/dist-packages/telegram/bot.py\", line 295, in _post\n",
            "    return self.request.post(\n",
            "  File \"/usr/local/lib/python3.10/dist-packages/telegram/utils/request.py\", line 356, in post\n",
            "    result = self._request_wrapper(\n",
            "  File \"/usr/local/lib/python3.10/dist-packages/telegram/utils/request.py\", line 283, in _request_wrapper\n",
            "    raise Conflict(message)\n",
            "telegram.error.Conflict: Conflict: terminated by other getUpdates request; make sure that only one bot instance is running\n",
            "ERROR:telegram.ext.updater:Error while getting Updates: Conflict: terminated by other getUpdates request; make sure that only one bot instance is running\n",
            "ERROR:telegram.ext.dispatcher:No error handlers are registered, logging exception.\n",
            "Traceback (most recent call last):\n",
            "  File \"/usr/local/lib/python3.10/dist-packages/telegram/ext/updater.py\", line 646, in _network_loop_retry\n",
            "    if not action_cb():\n",
            "  File \"/usr/local/lib/python3.10/dist-packages/telegram/ext/updater.py\", line 597, in polling_action_cb\n",
            "    updates = self.bot.get_updates(\n",
            "  File \"/usr/local/lib/python3.10/dist-packages/telegram/ext/extbot.py\", line 222, in get_updates\n",
            "    updates = super().get_updates(\n",
            "  File \"/usr/local/lib/python3.10/dist-packages/telegram/bot.py\", line 130, in decorator\n",
            "    result = func(*args, **kwargs)\n",
            "  File \"/usr/local/lib/python3.10/dist-packages/telegram/bot.py\", line 2861, in get_updates\n",
            "    self._post(\n",
            "  File \"/usr/local/lib/python3.10/dist-packages/telegram/bot.py\", line 295, in _post\n",
            "    return self.request.post(\n",
            "  File \"/usr/local/lib/python3.10/dist-packages/telegram/utils/request.py\", line 356, in post\n",
            "    result = self._request_wrapper(\n",
            "  File \"/usr/local/lib/python3.10/dist-packages/telegram/utils/request.py\", line 283, in _request_wrapper\n",
            "    raise Conflict(message)\n",
            "telegram.error.Conflict: Conflict: terminated by other getUpdates request; make sure that only one bot instance is running\n",
            "ERROR:telegram.ext.updater:Error while getting Updates: Conflict: terminated by other getUpdates request; make sure that only one bot instance is running\n",
            "ERROR:telegram.ext.dispatcher:No error handlers are registered, logging exception.\n",
            "Traceback (most recent call last):\n",
            "  File \"/usr/local/lib/python3.10/dist-packages/telegram/ext/updater.py\", line 646, in _network_loop_retry\n",
            "    if not action_cb():\n",
            "  File \"/usr/local/lib/python3.10/dist-packages/telegram/ext/updater.py\", line 597, in polling_action_cb\n",
            "    updates = self.bot.get_updates(\n",
            "  File \"/usr/local/lib/python3.10/dist-packages/telegram/ext/extbot.py\", line 222, in get_updates\n",
            "    updates = super().get_updates(\n",
            "  File \"/usr/local/lib/python3.10/dist-packages/telegram/bot.py\", line 130, in decorator\n",
            "    result = func(*args, **kwargs)\n",
            "  File \"/usr/local/lib/python3.10/dist-packages/telegram/bot.py\", line 2861, in get_updates\n",
            "    self._post(\n",
            "  File \"/usr/local/lib/python3.10/dist-packages/telegram/bot.py\", line 295, in _post\n",
            "    return self.request.post(\n",
            "  File \"/usr/local/lib/python3.10/dist-packages/telegram/utils/request.py\", line 356, in post\n",
            "    result = self._request_wrapper(\n",
            "  File \"/usr/local/lib/python3.10/dist-packages/telegram/utils/request.py\", line 283, in _request_wrapper\n",
            "    raise Conflict(message)\n",
            "telegram.error.Conflict: Conflict: terminated by other getUpdates request; make sure that only one bot instance is running\n",
            "ERROR:telegram.ext.updater:Error while getting Updates: Conflict: terminated by other getUpdates request; make sure that only one bot instance is running\n",
            "ERROR:telegram.ext.dispatcher:No error handlers are registered, logging exception.\n",
            "Traceback (most recent call last):\n",
            "  File \"/usr/local/lib/python3.10/dist-packages/telegram/ext/updater.py\", line 646, in _network_loop_retry\n",
            "    if not action_cb():\n",
            "  File \"/usr/local/lib/python3.10/dist-packages/telegram/ext/updater.py\", line 597, in polling_action_cb\n",
            "    updates = self.bot.get_updates(\n",
            "  File \"/usr/local/lib/python3.10/dist-packages/telegram/ext/extbot.py\", line 222, in get_updates\n",
            "    updates = super().get_updates(\n",
            "  File \"/usr/local/lib/python3.10/dist-packages/telegram/bot.py\", line 130, in decorator\n",
            "    result = func(*args, **kwargs)\n",
            "  File \"/usr/local/lib/python3.10/dist-packages/telegram/bot.py\", line 2861, in get_updates\n",
            "    self._post(\n",
            "  File \"/usr/local/lib/python3.10/dist-packages/telegram/bot.py\", line 295, in _post\n",
            "    return self.request.post(\n",
            "  File \"/usr/local/lib/python3.10/dist-packages/telegram/utils/request.py\", line 356, in post\n",
            "    result = self._request_wrapper(\n",
            "  File \"/usr/local/lib/python3.10/dist-packages/telegram/utils/request.py\", line 283, in _request_wrapper\n",
            "    raise Conflict(message)\n",
            "telegram.error.Conflict: Conflict: terminated by other getUpdates request; make sure that only one bot instance is running\n",
            "ERROR:telegram.ext.updater:Error while getting Updates: Conflict: terminated by other getUpdates request; make sure that only one bot instance is running\n",
            "ERROR:telegram.ext.dispatcher:No error handlers are registered, logging exception.\n",
            "Traceback (most recent call last):\n",
            "  File \"/usr/local/lib/python3.10/dist-packages/telegram/ext/updater.py\", line 646, in _network_loop_retry\n",
            "    if not action_cb():\n",
            "  File \"/usr/local/lib/python3.10/dist-packages/telegram/ext/updater.py\", line 597, in polling_action_cb\n",
            "    updates = self.bot.get_updates(\n",
            "  File \"/usr/local/lib/python3.10/dist-packages/telegram/ext/extbot.py\", line 222, in get_updates\n",
            "    updates = super().get_updates(\n",
            "  File \"/usr/local/lib/python3.10/dist-packages/telegram/bot.py\", line 130, in decorator\n",
            "    result = func(*args, **kwargs)\n",
            "  File \"/usr/local/lib/python3.10/dist-packages/telegram/bot.py\", line 2861, in get_updates\n",
            "    self._post(\n",
            "  File \"/usr/local/lib/python3.10/dist-packages/telegram/bot.py\", line 295, in _post\n",
            "    return self.request.post(\n",
            "  File \"/usr/local/lib/python3.10/dist-packages/telegram/utils/request.py\", line 356, in post\n",
            "    result = self._request_wrapper(\n",
            "  File \"/usr/local/lib/python3.10/dist-packages/telegram/utils/request.py\", line 283, in _request_wrapper\n",
            "    raise Conflict(message)\n",
            "telegram.error.Conflict: Conflict: terminated by other getUpdates request; make sure that only one bot instance is running\n",
            "ERROR:telegram.ext.updater:Error while getting Updates: Conflict: terminated by other getUpdates request; make sure that only one bot instance is running\n",
            "ERROR:telegram.ext.dispatcher:No error handlers are registered, logging exception.\n",
            "Traceback (most recent call last):\n",
            "  File \"/usr/local/lib/python3.10/dist-packages/telegram/ext/updater.py\", line 646, in _network_loop_retry\n",
            "    if not action_cb():\n",
            "  File \"/usr/local/lib/python3.10/dist-packages/telegram/ext/updater.py\", line 597, in polling_action_cb\n",
            "    updates = self.bot.get_updates(\n",
            "  File \"/usr/local/lib/python3.10/dist-packages/telegram/ext/extbot.py\", line 222, in get_updates\n",
            "    updates = super().get_updates(\n",
            "  File \"/usr/local/lib/python3.10/dist-packages/telegram/bot.py\", line 130, in decorator\n",
            "    result = func(*args, **kwargs)\n",
            "  File \"/usr/local/lib/python3.10/dist-packages/telegram/bot.py\", line 2861, in get_updates\n",
            "    self._post(\n",
            "  File \"/usr/local/lib/python3.10/dist-packages/telegram/bot.py\", line 295, in _post\n",
            "    return self.request.post(\n",
            "  File \"/usr/local/lib/python3.10/dist-packages/telegram/utils/request.py\", line 356, in post\n",
            "    result = self._request_wrapper(\n",
            "  File \"/usr/local/lib/python3.10/dist-packages/telegram/utils/request.py\", line 283, in _request_wrapper\n",
            "    raise Conflict(message)\n",
            "telegram.error.Conflict: Conflict: terminated by other getUpdates request; make sure that only one bot instance is running\n"
          ]
        }
      ],
      "source": [
        "def main() -> None:\n",
        "    try:\n",
        "        updater = Updater(TOKEN)\n",
        "        dp = updater.dispatcher\n",
        "\n",
        "        dp.add_handler(CommandHandler(\"start\", start))\n",
        "        dp.add_handler(CallbackQueryHandler(button))\n",
        "\n",
        "        updater.start_polling()\n",
        "        print(\"¬°Bot iniciado correctamente! üöÄ\")\n",
        "        print(\"Usa Ctrl+C para detener el bot\")\n",
        "        updater.idle()\n",
        "    except Exception as e:\n",
        "        print(f\"Error al iniciar el bot: {e}\")\n",
        "\n",
        "if __name__ == '__main__':\n",
        "    main()"
      ]
    }
  ],
  "metadata": {
    "colab": {
      "provenance": [],
      "authorship_tag": "ABX9TyP2h7BnU5jTl6XWR3hWM/k0",
      "include_colab_link": true
    },
    "kernelspec": {
      "display_name": "Python 3",
      "name": "python3"
    },
    "language_info": {
      "name": "python"
    }
  },
  "nbformat": 4,
  "nbformat_minor": 0
}